Workbook

Sheet Dashboard
A1: QUANNEX POC — CONTROL PANEL
A3: THESIS DEFENSE COUNTDOWN | D3: CEN STATUS | F3: Count | G3: ELEMENTS
A4: Days Remaining | B4: =DATE(2026,6,1)-TODAY() | D4: Days to meeting | E4: ="Apr 17 "&IF(DATE(2026,4,17)-TODAY()=0,"TODAY",IF(DATE(2026,4,17)-TODAY()=1,"TOMORROW",IF(DATE(2026,4,17)-TODAY()<0,"PAST",""))) | F4: =COUNTIF('60 Elements'!E2:E61,"PASS") | G4: Element Health
A5: Current Week | B5: =15-INT((DATE(2026,6,1)-TODAY())/7) | D5: =DATE(2026,4,17)-TODAY() | E5: until CEN | F5: =COUNTIF('60 Elements'!E2:E61,"WARN") | G5: 60 total checks
A6: Hard Deadline | B6: June 1, 2026 (noon) | D6: Blockers | E6: packaging actions | F6: =COUNTIF('60 Elements'!E2:E61,"—") | G6: ↑ live counts
A7: Next Milestone | B7: Phase 3 validation — ~April 17 | D7: =COUNTIF('CEN Deliverables'!F25:F32,"NOT DONE")+COUNTIF('CEN Deliverables'!F25:F32,"NOT STARTED")+COUNTIF('CEN Deliverables'!F25:F32,"BLOCKED") | E7: ="of "&COUNTA('CEN Deliverables'!F25:F32)&" total" | F7: =TEXT((60-COUNTIF('60 Elements'!E2:E61,"—"))/60,"0%") | G7: from 60 Elements
A9: Face # | B9: Name | C9: Dimension | D9: Status | E9: Key Metric | F9: Last Assessed | G9: Notes | H9: Health
A10: 1 | B10: Survival | C10: Correctness | D10: =IF(COUNTIFS('60 Elements'!$A$2:$A$61,$A10,'60 Elements'!$E$2:$E$61,"WARN")>0,"WARN",IF(COUNTIFS('60 Elements'!$A$2:$A$61,$A10,'60 Elements'!$E$2:$E$61,"PASS")>0,"PASS","—")) | E10: 0 syntax errors | F10: {=IFERROR(IF(SUMPRODUCT(('60 Elements'!$A$2:$A$61=$A10)*('60 Elements'!$G$2:$G$61<>""))=0,"—",TEXT(MAX(IF(('60 Elements'!$A$2:$A$61=$A10)*('60 Elements'!$G$2:$G$61<>""),DATEVALUE('60 Elements'!$G$2:$G$61))),"yyyy-mm-dd")),"—")} | H10: =IF(D10="PASS","✅",IF(D10="WARN","⚠️","❌"))
A11: 2 | B11: Foundation | C11: Structural Integrity | D11: =IF(COUNTIFS('60 Elements'!$A$2:$A$61,$A11,'60 Elements'!$E$2:$E$61,"WARN")>0,"WARN",IF(COUNTIFS('60 Elements'!$A$2:$A$61,$A11,'60 Elements'!$E$2:$E$61,"PASS")>0,"PASS","—")) | E11: PhiHarmonics consistent | F11: {=IFERROR(IF(SUMPRODUCT(('60 Elements'!$A$2:$A$61=$A11)*('60 Elements'!$G$2:$G$61<>""))=0,"—",TEXT(MAX(IF(('60 Elements'!$A$2:$A$61=$A11)*('60 Elements'!$G$2:$G$61<>""),DATEVALUE('60 Elements'!$G$2:$G$61))),"yyyy-mm-dd")),"—")} | H11: =IF(D11="PASS","✅",IF(D11="WARN","⚠️","❌"))
A12: 3 | B12: Clarity | C12: Documentation | D12: =IF(COUNTIFS('60 Elements'!$A$2:$A$61,$A12,'60 Elements'!$E$2:$E$61,"WARN")>0,"WARN",IF(COUNTIFS('60 Elements'!$A$2:$A$61,$A12,'60 Elements'!$E$2:$E$61,"PASS")>0,"PASS","—")) | E12: α-drift class patched | F12: {=IFERROR(IF(SUMPRODUCT(('60 Elements'!$A$2:$A$61=$A12)*('60 Elements'!$G$2:$G$61<>""))=0,"—",TEXT(MAX(IF(('60 Elements'!$A$2:$A$61=$A12)*('60 Elements'!$G$2:$G$61<>""),DATEVALUE('60 Elements'!$G$2:$G$61))),"yyyy-mm-dd")),"—")} | G12: Doc-drift risk ongoing | H12: =IF(D12="PASS","✅",IF(D12="WARN","⚠️","❌"))
A13: 4 | B13: Harmony | C13: DRY & Hygiene | D13: =IF(COUNTIFS('60 Elements'!$A$2:$A$61,$A13,'60 Elements'!$E$2:$E$61,"WARN")>0,"WARN",IF(COUNTIFS('60 Elements'!$A$2:$A$61,$A13,'60 Elements'!$E$2:$E$61,"PASS")>0,"PASS","—")) | E13: Logger migration done | F13: {=IFERROR(IF(SUMPRODUCT(('60 Elements'!$A$2:$A$61=$A13)*('60 Elements'!$G$2:$G$61<>""))=0,"—",TEXT(MAX(IF(('60 Elements'!$A$2:$A$61=$A13)*('60 Elements'!$G$2:$G$61<>""),DATEVALUE('60 Elements'!$G$2:$G$61))),"yyyy-mm-dd")),"—")} | G13: 3 spectral files = tech debt | H13: =IF(D13="PASS","✅",IF(D13="WARN","⚠️","❌"))
A14: 5 | B14: Signal | C14: Honest Output | D14: =IF(COUNTIFS('60 Elements'!$A$2:$A$61,$A14,'60 Elements'!$E$2:$E$61,"WARN")>0,"WARN",IF(COUNTIFS('60 Elements'!$A$2:$A$61,$A14,'60 Elements'!$E$2:$E$61,"PASS")>0,"PASS","—")) | E14: Test honesty verified | F14: {=IFERROR(IF(SUMPRODUCT(('60 Elements'!$A$2:$A$61=$A14)*('60 Elements'!$G$2:$G$61<>""))=0,"—",TEXT(MAX(IF(('60 Elements'!$A$2:$A$61=$A14)*('60 Elements'!$G$2:$G$61<>""),DATEVALUE('60 Elements'!$G$2:$G$61))),"yyyy-mm-dd")),"—")} | G14: Stress test was once dishonest | H14: =IF(D14="PASS","✅",IF(D14="WARN","⚠️","❌"))
A15: 6 | B15: Consciousness | C15: Intelligence Interop | D15: =IF(COUNTIFS('60 Elements'!$A$2:$A$61,$A15,'60 Elements'!$E$2:$E$61,"WARN")>0,"WARN",IF(COUNTIFS('60 Elements'!$A$2:$A$61,$A15,'60 Elements'!$E$2:$E$61,"PASS")>0,"PASS","—")) | E15: CLAUDE.md + hooks active | F15: {=IFERROR(IF(SUMPRODUCT(('60 Elements'!$A$2:$A$61=$A15)*('60 Elements'!$G$2:$G$61<>""))=0,"—",TEXT(MAX(IF(('60 Elements'!$A$2:$A$61=$A15)*('60 Elements'!$G$2:$G$61<>""),DATEVALUE('60 Elements'!$G$2:$G$61))),"yyyy-mm-dd")),"—")} | H15: =IF(D15="PASS","✅",IF(D15="WARN","⚠️","❌"))
A16: 7 | B16: Coherence | C16: Pattern Alignment | D16: =IF(COUNTIFS('60 Elements'!$A$2:$A$61,$A16,'60 Elements'!$E$2:$E$61,"WARN")>0,"WARN",IF(COUNTIFS('60 Elements'!$A$2:$A$61,$A16,'60 Elements'!$E$2:$E$61,"PASS")>0,"PASS","—")) | E16: 5-pass engine intact | F16: {=IFERROR(IF(SUMPRODUCT(('60 Elements'!$A$2:$A$61=$A16)*('60 Elements'!$G$2:$G$61<>""))=0,"—",TEXT(MAX(IF(('60 Elements'!$A$2:$A$61=$A16)*('60 Elements'!$G$2:$G$61<>""),DATEVALUE('60 Elements'!$G$2:$G$61))),"yyyy-mm-dd")),"—")} | H16: =IF(D16="PASS","✅",IF(D16="WARN","⚠️","❌"))
A17: 8 | B17: Resilience | C17: Risk & Security | D17: =IF(COUNTIFS('60 Elements'!$A$2:$A$61,$A17,'60 Elements'!$E$2:$E$61,"WARN")>0,"WARN",IF(COUNTIFS('60 Elements'!$A$2:$A$61,$A17,'60 Elements'!$E$2:$E$61,"PASS")>0,"PASS","—")) | E17: Circuit breaker active | F17: {=IFERROR(IF(SUMPRODUCT(('60 Elements'!$A$2:$A$61=$A17)*('60 Elements'!$G$2:$G$61<>""))=0,"—",TEXT(MAX(IF(('60 Elements'!$A$2:$A$61=$A17)*('60 Elements'!$G$2:$G$61<>""),DATEVALUE('60 Elements'!$G$2:$G$61))),"yyyy-mm-dd")),"—")} | G17: Edge cases need re-testing | H17: =IF(D17="PASS","✅",IF(D17="WARN","⚠️","❌"))
A18: 9 | B18: Growth | C18: Regenerative Quality | D18: =IF(COUNTIFS('60 Elements'!$A$2:$A$61,$A18,'60 Elements'!$E$2:$E$61,"WARN")>0,"WARN",IF(COUNTIFS('60 Elements'!$A$2:$A$61,$A18,'60 Elements'!$E$2:$E$61,"PASS")>0,"PASS","—")) | E18: Self-dev pattern installed | F18: {=IFERROR(IF(SUMPRODUCT(('60 Elements'!$A$2:$A$61=$A18)*('60 Elements'!$G$2:$G$61<>""))=0,"—",TEXT(MAX(IF(('60 Elements'!$A$2:$A$61=$A18)*('60 Elements'!$G$2:$G$61<>""),DATEVALUE('60 Elements'!$G$2:$G$61))),"yyyy-mm-dd")),"—")} | G18: 13 growth ideas pending | H18: =IF(D18="PASS","✅",IF(D18="WARN","⚠️","❌"))
A19: 10 | B19: Integrity | C19: Test Coverage | D19: =IF(COUNTIFS('60 Elements'!$A$2:$A$61,$A19,'60 Elements'!$E$2:$E$61,"WARN")>0,"WARN",IF(COUNTIFS('60 Elements'!$A$2:$A$61,$A19,'60 Elements'!$E$2:$E$61,"PASS")>0,"PASS","—")) | E19: 306/306 green | F19: {=IFERROR(IF(SUMPRODUCT(('60 Elements'!$A$2:$A$61=$A19)*('60 Elements'!$G$2:$G$61<>""))=0,"—",TEXT(MAX(IF(('60 Elements'!$A$2:$A$61=$A19)*('60 Elements'!$G$2:$G$61<>""),DATEVALUE('60 Elements'!$G$2:$G$61))),"yyyy-mm-dd")),"—")} | G19: Smoke test needs HTTP server | H19: =IF(D19="PASS","✅",IF(D19="WARN","⚠️","❌"))
A20: 11 | B20: Discovery | C20: Research & Creativity | D20: =IF(COUNTIFS('60 Elements'!$A$2:$A$61,$A20,'60 Elements'!$E$2:$E$61,"WARN")>0,"WARN",IF(COUNTIFS('60 Elements'!$A$2:$A$61,$A20,'60 Elements'!$E$2:$E$61,"PASS")>0,"PASS","—")) | E20: 11 emergent truths found | F20: {=IFERROR(IF(SUMPRODUCT(('60 Elements'!$A$2:$A$61=$A20)*('60 Elements'!$G$2:$G$61<>""))=0,"—",TEXT(MAX(IF(('60 Elements'!$A$2:$A$61=$A20)*('60 Elements'!$G$2:$G$61<>""),DATEVALUE('60 Elements'!$G$2:$G$61))),"yyyy-mm-dd")),"—")} | H20: =IF(D20="PASS","✅",IF(D20="WARN","⚠️","❌"))
A21: 12 | B21: Radiance | C21: Sustainable Exponentiality | D21: =IF(COUNTIFS('60 Elements'!$A$2:$A$61,$A21,'60 Elements'!$E$2:$E$61,"WARN")>0,"WARN",IF(COUNTIFS('60 Elements'!$A$2:$A$61,$A21,'60 Elements'!$E$2:$E$61,"PASS")>0,"PASS","—")) | E21: Spiral loop self-applying | F21: {=IFERROR(IF(SUMPRODUCT(('60 Elements'!$A$2:$A$61=$A21)*('60 Elements'!$G$2:$G$61<>""))=0,"—",TEXT(MAX(IF(('60 Elements'!$A$2:$A$61=$A21)*('60 Elements'!$G$2:$G$61<>""),DATEVALUE('60 Elements'!$G$2:$G$61))),"yyyy-mm-dd")),"—")} | G21: Law 1 inscribed | H21: =IF(D21="PASS","✅",IF(D21="WARN","⚠️","❌"))
A23: Spiral Octave Songbook v1 (Phase 4 Commitment) | B23: Phase 4 | C23: 2026-04-15 | D23: RADIANT | E23: 9.25/10 | F23: 12/12 faces >= 9/10 | G23: Artifact committed, May package scheduled
A24: OVERALL VERDICT | D24: =IF(AND(COUNTIF('CEN Deliverables'!F25:F32,"NOT DONE")+COUNTIF('CEN Deliverables'!F25:F32,"NOT STARTED")+COUNTIF('CEN Deliverables'!F25:F32,"BLOCKED")>0,(DATE(2026,4,17)-TODAY())<=3),"🔴 CEN MEETING AT RISK",IF(OR(COUNTIF(D10:D21,"WARN")>=3,COUNTIF('60 Elements'!E2:E61,"—")/60>0.4),"🟠 ATTENTION NEEDED",IF(OR(COUNTIF(D10:D21,"WARN")>=1,COUNTIF('60 Elements'!E2:E61,"—")/60>0.2),"🟡 MONITORING","🟢 CLEAN"))) | E24: =IF(LEFT(D24,1)="🔴",""&COUNTIF('CEN Deliverables'!F25:F32,"NOT DONE")+COUNTIF('CEN Deliverables'!F25:F32,"NOT STARTED")+COUNTIF('CEN Deliverables'!F25:F32,"BLOCKED")&" CEN actions not done, "&(DATE(2026,4,17)-TODAY())&"d to meeting",IF(LEFT(D24,1)="🟠",COUNTIF(D10:D21,"WARN")&" WARN faces, "&TEXT(COUNTIF('60 Elements'!E2:E61,"—")/60,"0%")&" unassessed",IF(LEFT(D24,1)="🟡",COUNTIF(D10:D21,"WARN")&" WARN faces, "&TEXT(COUNTIF('60 Elements'!E2:E61,"—")/60,"0%")&" unassessed","All faces PASS, CEN on track")))
A25: IFC BACHELOR SCOPE | B25: =COUNTIF('Thesis Evidence'!I4:I13,"Bachelor")&" in scope" | C25: =COUNTIF('Thesis Evidence'!I4:I13,"Master")&" stretch (MSc)" | D25: =COUNTIF('Thesis Evidence'!I4:I13,"PhD")&" out of scope (PhD)" | E25: ← focus here for IFC bachelor
A26: Law 1: "Substrate failures are invisible until asked about. Therefore: ask about them on a schedule, not on suspicion."

Sheet Priority Actions
A1: QUANNEX POC — PRIORITY ACTIONS
A2: Auto-generated view: WARNs · Unassessed elements · CEN blockers · Thesis blockers | B2: ="Last refreshed: "&TEXT(TODAY(),"MMM D, YYYY")
A4: 🚨 SECTION 1: CEN CRITICAL ACTIONS (April 17 meeting — TOMORROW)
A5: Priority | B5: Action | C5: Source / Notes | D5: Effort | E5: Status
A6: CRITICAL | B6: Create CEN company template for POC | C6: RawScores_Frozen.md — normalized arrays ready. Unlocks 3D viz + shadow analysis | D6: ~2 hrs | E6: NOT DONE
A7: CRITICAL | B7: Create Phase 3 validation presentation (PPTX) | C7: Phase 2 evidence package (C1-C4 docs) — coherence portrait + key findings | D7: ~3 hrs | E7: NOT DONE
A8: CRITICAL | B8: Create CEN-facing coherence summary (PDF, 2-4 pages) | C8: C1 Vector Diagnostics + C2 Breath + C3 Divergence — executive leave-behind | D8: ~2 hrs | E8: NOT DONE
A9: HIGH | B9: Package Phase 1 deliverables (overdue since March) | C9: Interview synthesis (57KB) + face mapping (33KB) — Deliverables/Phase 1/ EMPTY | D9: ~1 hr | E9: NOT DONE
A10: HIGH | B10: Package Phase 2 deliverables (overdue since April) | C10: Evidence package C1-C4 + BSC + breath analysis — Deliverables/Phase 2/ EMPTY | D10: ~2 hrs | E10: NOT DONE
A11: ⚠️ SECTION 2: POC WARN FACES — live from 60 Elements
A12: Face | B12: Element | C12: Check Description | D12: Evidence / Notes | E12: Last Checked | F12: Status | G12: Source row #
A13: {=IFERROR(INDEX('60 Elements'!B:B,SMALL(IF('60 Elements'!E$2:E$61="WARN",ROW('60 Elements'!E$2:E$61)),1)),"")} | B13: {=IFERROR(INDEX('60 Elements'!C:C,SMALL(IF('60 Elements'!E$2:E$61="WARN",ROW('60 Elements'!E$2:E$61)),1)),"")} | C13: {=IFERROR(INDEX('60 Elements'!D:D,SMALL(IF('60 Elements'!E$2:E$61="WARN",ROW('60 Elements'!E$2:E$61)),1)),"")} | D13: {=IFERROR(INDEX('60 Elements'!F:F,SMALL(IF('60 Elements'!E$2:E$61="WARN",ROW('60 Elements'!E$2:E$61)),1)),"")} | E13: {=IFERROR(INDEX('60 Elements'!G:G,SMALL(IF('60 Elements'!E$2:E$61="WARN",ROW('60 Elements'!E$2:E$61)),1)),"")} | F13: {=IFERROR(INDEX('60 Elements'!E:E,SMALL(IF('60 Elements'!E$2:E$61="WARN",ROW('60 Elements'!E$2:E$61)),1)),"")} | G13: {=IFERROR(SMALL(IF('60 Elements'!E$2:E$61="WARN",ROW('60 Elements'!E$2:E$61)-ROW('60 Elements'!E$2)+2),1),"")}
A14: {=IFERROR(INDEX('60 Elements'!B:B,SMALL(IF('60 Elements'!E$2:E$61="WARN",ROW('60 Elements'!E$2:E$61)),2)),"")} | B14: {=IFERROR(INDEX('60 Elements'!C:C,SMALL(IF('60 Elements'!E$2:E$61="WARN",ROW('60 Elements'!E$2:E$61)),2)),"")} | C14: {=IFERROR(INDEX('60 Elements'!D:D,SMALL(IF('60 Elements'!E$2:E$61="WARN",ROW('60 Elements'!E$2:E$61)),2)),"")} | D14: {=IFERROR(INDEX('60 Elements'!F:F,SMALL(IF('60 Elements'!E$2:E$61="WARN",ROW('60 Elements'!E$2:E$61)),2)),"")} | E14: {=IFERROR(INDEX('60 Elements'!G:G,SMALL(IF('60 Elements'!E$2:E$61="WARN",ROW('60 Elements'!E$2:E$61)),2)),"")} | F14: {=IFERROR(INDEX('60 Elements'!E:E,SMALL(IF('60 Elements'!E$2:E$61="WARN",ROW('60 Elements'!E$2:E$61)),2)),"")} | G14: {=IFERROR(SMALL(IF('60 Elements'!E$2:E$61="WARN",ROW('60 Elements'!E$2:E$61)-ROW('60 Elements'!E$2)+2),2),"")}
A15: {=IFERROR(INDEX('60 Elements'!B:B,SMALL(IF('60 Elements'!E$2:E$61="WARN",ROW('60 Elements'!E$2:E$61)),3)),"")} | B15: {=IFERROR(INDEX('60 Elements'!C:C,SMALL(IF('60 Elements'!E$2:E$61="WARN",ROW('60 Elements'!E$2:E$61)),3)),"")} | C15: {=IFERROR(INDEX('60 Elements'!D:D,SMALL(IF('60 Elements'!E$2:E$61="WARN",ROW('60 Elements'!E$2:E$61)),3)),"")} | D15: {=IFERROR(INDEX('60 Elements'!F:F,SMALL(IF('60 Elements'!E$2:E$61="WARN",ROW('60 Elements'!E$2:E$61)),3)),"")} | E15: {=IFERROR(INDEX('60 Elements'!G:G,SMALL(IF('60 Elements'!E$2:E$61="WARN",ROW('60 Elements'!E$2:E$61)),3)),"")} | F15: {=IFERROR(INDEX('60 Elements'!E:E,SMALL(IF('60 Elements'!E$2:E$61="WARN",ROW('60 Elements'!E$2:E$61)),3)),"")} | G15: {=IFERROR(SMALL(IF('60 Elements'!E$2:E$61="WARN",ROW('60 Elements'!E$2:E$61)-ROW('60 Elements'!E$2)+2),3),"")}
A16: {=IFERROR(INDEX('60 Elements'!B:B,SMALL(IF('60 Elements'!E$2:E$61="WARN",ROW('60 Elements'!E$2:E$61)),4)),"")} | B16: {=IFERROR(INDEX('60 Elements'!C:C,SMALL(IF('60 Elements'!E$2:E$61="WARN",ROW('60 Elements'!E$2:E$61)),4)),"")} | C16: {=IFERROR(INDEX('60 Elements'!D:D,SMALL(IF('60 Elements'!E$2:E$61="WARN",ROW('60 Elements'!E$2:E$61)),4)),"")} | D16: {=IFERROR(INDEX('60 Elements'!F:F,SMALL(IF('60 Elements'!E$2:E$61="WARN",ROW('60 Elements'!E$2:E$61)),4)),"")} | E16: {=IFERROR(INDEX('60 Elements'!G:G,SMALL(IF('60 Elements'!E$2:E$61="WARN",ROW('60 Elements'!E$2:E$61)),4)),"")} | F16: {=IFERROR(INDEX('60 Elements'!E:E,SMALL(IF('60 Elements'!E$2:E$61="WARN",ROW('60 Elements'!E$2:E$61)),4)),"")} | G16: {=IFERROR(SMALL(IF('60 Elements'!E$2:E$61="WARN",ROW('60 Elements'!E$2:E$61)-ROW('60 Elements'!E$2)+2),4),"")}
A17: {=IFERROR(INDEX('60 Elements'!B:B,SMALL(IF('60 Elements'!E$2:E$61="WARN",ROW('60 Elements'!E$2:E$61)),5)),"")} | B17: {=IFERROR(INDEX('60 Elements'!C:C,SMALL(IF('60 Elements'!E$2:E$61="WARN",ROW('60 Elements'!E$2:E$61)),5)),"")} | C17: {=IFERROR(INDEX('60 Elements'!D:D,SMALL(IF('60 Elements'!E$2:E$61="WARN",ROW('60 Elements'!E$2:E$61)),5)),"")} | D17: {=IFERROR(INDEX('60 Elements'!F:F,SMALL(IF('60 Elements'!E$2:E$61="WARN",ROW('60 Elements'!E$2:E$61)),5)),"")} | E17: {=IFERROR(INDEX('60 Elements'!G:G,SMALL(IF('60 Elements'!E$2:E$61="WARN",ROW('60 Elements'!E$2:E$61)),5)),"")} | F17: {=IFERROR(INDEX('60 Elements'!E:E,SMALL(IF('60 Elements'!E$2:E$61="WARN",ROW('60 Elements'!E$2:E$61)),5)),"")} | G17: {=IFERROR(SMALL(IF('60 Elements'!E$2:E$61="WARN",ROW('60 Elements'!E$2:E$61)-ROW('60 Elements'!E$2)+2),5),"")}
A18: {=IFERROR(INDEX('60 Elements'!B:B,SMALL(IF('60 Elements'!E$2:E$61="WARN",ROW('60 Elements'!E$2:E$61)),6)),"")} | B18: {=IFERROR(INDEX('60 Elements'!C:C,SMALL(IF('60 Elements'!E$2:E$61="WARN",ROW('60 Elements'!E$2:E$61)),6)),"")} | C18: {=IFERROR(INDEX('60 Elements'!D:D,SMALL(IF('60 Elements'!E$2:E$61="WARN",ROW('60 Elements'!E$2:E$61)),6)),"")} | D18: {=IFERROR(INDEX('60 Elements'!F:F,SMALL(IF('60 Elements'!E$2:E$61="WARN",ROW('60 Elements'!E$2:E$61)),6)),"")} | E18: {=IFERROR(INDEX('60 Elements'!G:G,SMALL(IF('60 Elements'!E$2:E$61="WARN",ROW('60 Elements'!E$2:E$61)),6)),"")} | F18: {=IFERROR(INDEX('60 Elements'!E:E,SMALL(IF('60 Elements'!E$2:E$61="WARN",ROW('60 Elements'!E$2:E$61)),6)),"")} | G18: {=IFERROR(SMALL(IF('60 Elements'!E$2:E$61="WARN",ROW('60 Elements'!E$2:E$61)-ROW('60 Elements'!E$2)+2),6),"")}
A19: {=IFERROR(INDEX('60 Elements'!B:B,SMALL(IF('60 Elements'!E$2:E$61="WARN",ROW('60 Elements'!E$2:E$61)),7)),"")} | B19: {=IFERROR(INDEX('60 Elements'!C:C,SMALL(IF('60 Elements'!E$2:E$61="WARN",ROW('60 Elements'!E$2:E$61)),7)),"")} | C19: {=IFERROR(INDEX('60 Elements'!D:D,SMALL(IF('60 Elements'!E$2:E$61="WARN",ROW('60 Elements'!E$2:E$61)),7)),"")} | D19: {=IFERROR(INDEX('60 Elements'!F:F,SMALL(IF('60 Elements'!E$2:E$61="WARN",ROW('60 Elements'!E$2:E$61)),7)),"")} | E19: {=IFERROR(INDEX('60 Elements'!G:G,SMALL(IF('60 Elements'!E$2:E$61="WARN",ROW('60 Elements'!E$2:E$61)),7)),"")} | F19: {=IFERROR(INDEX('60 Elements'!E:E,SMALL(IF('60 Elements'!E$2:E$61="WARN",ROW('60 Elements'!E$2:E$61)),7)),"")} | G19: {=IFERROR(SMALL(IF('60 Elements'!E$2:E$61="WARN",ROW('60 Elements'!E$2:E$61)-ROW('60 Elements'!E$2)+2),7),"")}
A20: {=IFERROR(INDEX('60 Elements'!B:B,SMALL(IF('60 Elements'!E$2:E$61="WARN",ROW('60 Elements'!E$2:E$61)),8)),"")} | B20: {=IFERROR(INDEX('60 Elements'!C:C,SMALL(IF('60 Elements'!E$2:E$61="WARN",ROW('60 Elements'!E$2:E$61)),8)),"")} | C20: {=IFERROR(INDEX('60 Elements'!D:D,SMALL(IF('60 Elements'!E$2:E$61="WARN",ROW('60 Elements'!E$2:E$61)),8)),"")} | D20: {=IFERROR(INDEX('60 Elements'!F:F,SMALL(IF('60 Elements'!E$2:E$61="WARN",ROW('60 Elements'!E$2:E$61)),8)),"")} | E20: {=IFERROR(INDEX('60 Elements'!G:G,SMALL(IF('60 Elements'!E$2:E$61="WARN",ROW('60 Elements'!E$2:E$61)),8)),"")} | F20: {=IFERROR(INDEX('60 Elements'!E:E,SMALL(IF('60 Elements'!E$2:E$61="WARN",ROW('60 Elements'!E$2:E$61)),8)),"")} | G20: {=IFERROR(SMALL(IF('60 Elements'!E$2:E$61="WARN",ROW('60 Elements'!E$2:E$61)-ROW('60 Elements'!E$2)+2),8),"")}
A21: {=IFERROR(INDEX('60 Elements'!B:B,SMALL(IF('60 Elements'!E$2:E$61="WARN",ROW('60 Elements'!E$2:E$61)),9)),"")} | B21: {=IFERROR(INDEX('60 Elements'!C:C,SMALL(IF('60 Elements'!E$2:E$61="WARN",ROW('60 Elements'!E$2:E$61)),9)),"")} | C21: {=IFERROR(INDEX('60 Elements'!D:D,SMALL(IF('60 Elements'!E$2:E$61="WARN",ROW('60 Elements'!E$2:E$61)),9)),"")} | D21: {=IFERROR(INDEX('60 Elements'!F:F,SMALL(IF('60 Elements'!E$2:E$61="WARN",ROW('60 Elements'!E$2:E$61)),9)),"")} | E21: {=IFERROR(INDEX('60 Elements'!G:G,SMALL(IF('60 Elements'!E$2:E$61="WARN",ROW('60 Elements'!E$2:E$61)),9)),"")} | F21: {=IFERROR(INDEX('60 Elements'!E:E,SMALL(IF('60 Elements'!E$2:E$61="WARN",ROW('60 Elements'!E$2:E$61)),9)),"")} | G21: {=IFERROR(SMALL(IF('60 Elements'!E$2:E$61="WARN",ROW('60 Elements'!E$2:E$61)-ROW('60 Elements'!E$2)+2),9),"")}
A22: {=IFERROR(INDEX('60 Elements'!B:B,SMALL(IF('60 Elements'!E$2:E$61="WARN",ROW('60 Elements'!E$2:E$61)),10)),"")} | B22: {=IFERROR(INDEX('60 Elements'!C:C,SMALL(IF('60 Elements'!E$2:E$61="WARN",ROW('60 Elements'!E$2:E$61)),10)),"")} | C22: {=IFERROR(INDEX('60 Elements'!D:D,SMALL(IF('60 Elements'!E$2:E$61="WARN",ROW('60 Elements'!E$2:E$61)),10)),"")} | D22: {=IFERROR(INDEX('60 Elements'!F:F,SMALL(IF('60 Elements'!E$2:E$61="WARN",ROW('60 Elements'!E$2:E$61)),10)),"")} | E22: {=IFERROR(INDEX('60 Elements'!G:G,SMALL(IF('60 Elements'!E$2:E$61="WARN",ROW('60 Elements'!E$2:E$61)),10)),"")} | F22: {=IFERROR(INDEX('60 Elements'!E:E,SMALL(IF('60 Elements'!E$2:E$61="WARN",ROW('60 Elements'!E$2:E$61)),10)),"")} | G22: {=IFERROR(SMALL(IF('60 Elements'!E$2:E$61="WARN",ROW('60 Elements'!E$2:E$61)-ROW('60 Elements'!E$2)+2),10),"")}
A24: 🔬 SECTION 3: THESIS BLOCKERS
A25: Blocker | B25: Detail | C25: Blocked On | D25: Chapter(s) | E25: Resolve By
A26: BLOCKED | B26: ='Thesis Evidence'!A26 | C26: ='Thesis Evidence'!B26 | D26: Ch 2-5 | E26: Before May 1 writing window
A27: BLOCKED | B27: ='Thesis Evidence'!A27 | C27: ='Thesis Evidence'!B27 | D27: Ch 5 | E27: Unblocked once CEN template created
A29: 🔬 SECTION 4: UNASSESSED ELEMENTS — live from 60 Elements
A30: Face | B30: Element | C30: Check Description | D30: Evidence / Notes | E30: Status | F30: Source row #
A31: {=IFERROR(INDEX('60 Elements'!B:B,SMALL(IF('60 Elements'!E$2:E$61="—",ROW('60 Elements'!E$2:E$61)),1)),"")} | B31: {=IFERROR(INDEX('60 Elements'!C:C,SMALL(IF('60 Elements'!E$2:E$61="—",ROW('60 Elements'!E$2:E$61)),1)),"")} | C31: {=IFERROR(INDEX('60 Elements'!D:D,SMALL(IF('60 Elements'!E$2:E$61="—",ROW('60 Elements'!E$2:E$61)),1)),"")} | D31: {=IFERROR(INDEX('60 Elements'!F:F,SMALL(IF('60 Elements'!E$2:E$61="—",ROW('60 Elements'!E$2:E$61)),1)),"")} | E31: {=IFERROR(INDEX('60 Elements'!E:E,SMALL(IF('60 Elements'!E$2:E$61="—",ROW('60 Elements'!E$2:E$61)),1)),"")} | F31: {=IFERROR(SMALL(IF('60 Elements'!E$2:E$61="—",ROW('60 Elements'!E$2:E$61)-ROW('60 Elements'!E$2)+2),1),"")}
A32: {=IFERROR(INDEX('60 Elements'!B:B,SMALL(IF('60 Elements'!E$2:E$61="—",ROW('60 Elements'!E$2:E$61)),2)),"")} | B32: {=IFERROR(INDEX('60 Elements'!C:C,SMALL(IF('60 Elements'!E$2:E$61="—",ROW('60 Elements'!E$2:E$61)),2)),"")} | C32: {=IFERROR(INDEX('60 Elements'!D:D,SMALL(IF('60 Elements'!E$2:E$61="—",ROW('60 Elements'!E$2:E$61)),2)),"")} | D32: {=IFERROR(INDEX('60 Elements'!F:F,SMALL(IF('60 Elements'!E$2:E$61="—",ROW('60 Elements'!E$2:E$61)),2)),"")} | E32: {=IFERROR(INDEX('60 Elements'!E:E,SMALL(IF('60 Elements'!E$2:E$61="—",ROW('60 Elements'!E$2:E$61)),2)),"")} | F32: {=IFERROR(SMALL(IF('60 Elements'!E$2:E$61="—",ROW('60 Elements'!E$2:E$61)-ROW('60 Elements'!E$2)+2),2),"")}
A33: {=IFERROR(INDEX('60 Elements'!B:B,SMALL(IF('60 Elements'!E$2:E$61="—",ROW('60 Elements'!E$2:E$61)),3)),"")} | B33: {=IFERROR(INDEX('60 Elements'!C:C,SMALL(IF('60 Elements'!E$2:E$61="—",ROW('60 Elements'!E$2:E$61)),3)),"")} | C33: {=IFERROR(INDEX('60 Elements'!D:D,SMALL(IF('60 Elements'!E$2:E$61="—",ROW('60 Elements'!E$2:E$61)),3)),"")} | D33: {=IFERROR(INDEX('60 Elements'!F:F,SMALL(IF('60 Elements'!E$2:E$61="—",ROW('60 Elements'!E$2:E$61)),3)),"")} | E33: {=IFERROR(INDEX('60 Elements'!E:E,SMALL(IF('60 Elements'!E$2:E$61="—",ROW('60 Elements'!E$2:E$61)),3)),"")} | F33: {=IFERROR(SMALL(IF('60 Elements'!E$2:E$61="—",ROW('60 Elements'!E$2:E$61)-ROW('60 Elements'!E$2)+2),3),"")}
A34: {=IFERROR(INDEX('60 Elements'!B:B,SMALL(IF('60 Elements'!E$2:E$61="—",ROW('60 Elements'!E$2:E$61)),4)),"")} | B34: {=IFERROR(INDEX('60 Elements'!C:C,SMALL(IF('60 Elements'!E$2:E$61="—",ROW('60 Elements'!E$2:E$61)),4)),"")} | C34: {=IFERROR(INDEX('60 Elements'!D:D,SMALL(IF('60 Elements'!E$2:E$61="—",ROW('60 Elements'!E$2:E$61)),4)),"")} | D34: {=IFERROR(INDEX('60 Elements'!F:F,SMALL(IF('60 Elements'!E$2:E$61="—",ROW('60 Elements'!E$2:E$61)),4)),"")} | E34: {=IFERROR(INDEX('60 Elements'!E:E,SMALL(IF('60 Elements'!E$2:E$61="—",ROW('60 Elements'!E$2:E$61)),4)),"")} | F34: {=IFERROR(SMALL(IF('60 Elements'!E$2:E$61="—",ROW('60 Elements'!E$2:E$61)-ROW('60 Elements'!E$2)+2),4),"")}
A35: {=IFERROR(INDEX('60 Elements'!B:B,SMALL(IF('60 Elements'!E$2:E$61="—",ROW('60 Elements'!E$2:E$61)),5)),"")} | B35: {=IFERROR(INDEX('60 Elements'!C:C,SMALL(IF('60 Elements'!E$2:E$61="—",ROW('60 Elements'!E$2:E$61)),5)),"")} | C35: {=IFERROR(INDEX('60 Elements'!D:D,SMALL(IF('60 Elements'!E$2:E$61="—",ROW('60 Elements'!E$2:E$61)),5)),"")} | D35: {=IFERROR(INDEX('60 Elements'!F:F,SMALL(IF('60 Elements'!E$2:E$61="—",ROW('60 Elements'!E$2:E$61)),5)),"")} | E35: {=IFERROR(INDEX('60 Elements'!E:E,SMALL(IF('60 Elements'!E$2:E$61="—",ROW('60 Elements'!E$2:E$61)),5)),"")} | F35: {=IFERROR(SMALL(IF('60 Elements'!E$2:E$61="—",ROW('60 Elements'!E$2:E$61)-ROW('60 Elements'!E$2)+2),5),"")}
A36: {=IFERROR(INDEX('60 Elements'!B:B,SMALL(IF('60 Elements'!E$2:E$61="—",ROW('60 Elements'!E$2:E$61)),6)),"")} | B36: {=IFERROR(INDEX('60 Elements'!C:C,SMALL(IF('60 Elements'!E$2:E$61="—",ROW('60 Elements'!E$2:E$61)),6)),"")} | C36: {=IFERROR(INDEX('60 Elements'!D:D,SMALL(IF('60 Elements'!E$2:E$61="—",ROW('60 Elements'!E$2:E$61)),6)),"")} | D36: {=IFERROR(INDEX('60 Elements'!F:F,SMALL(IF('60 Elements'!E$2:E$61="—",ROW('60 Elements'!E$2:E$61)),6)),"")} | E36: {=IFERROR(INDEX('60 Elements'!E:E,SMALL(IF('60 Elements'!E$2:E$61="—",ROW('60 Elements'!E$2:E$61)),6)),"")} | F36: {=IFERROR(SMALL(IF('60 Elements'!E$2:E$61="—",ROW('60 Elements'!E$2:E$61)-ROW('60 Elements'!E$2)+2),6),"")}
A37: {=IFERROR(INDEX('60 Elements'!B:B,SMALL(IF('60 Elements'!E$2:E$61="—",ROW('60 Elements'!E$2:E$61)),7)),"")} | B37: {=IFERROR(INDEX('60 Elements'!C:C,SMALL(IF('60 Elements'!E$2:E$61="—",ROW('60 Elements'!E$2:E$61)),7)),"")} | C37: {=IFERROR(INDEX('60 Elements'!D:D,SMALL(IF('60 Elements'!E$2:E$61="—",ROW('60 Elements'!E$2:E$61)),7)),"")} | D37: {=IFERROR(INDEX('60 Elements'!F:F,SMALL(IF('60 Elements'!E$2:E$61="—",ROW('60 Elements'!E$2:E$61)),7)),"")} | E37: {=IFERROR(INDEX('60 Elements'!E:E,SMALL(IF('60 Elements'!E$2:E$61="—",ROW('60 Elements'!E$2:E$61)),7)),"")} | F37: {=IFERROR(SMALL(IF('60 Elements'!E$2:E$61="—",ROW('60 Elements'!E$2:E$61)-ROW('60 Elements'!E$2)+2),7),"")}
A38: {=IFERROR(INDEX('60 Elements'!B:B,SMALL(IF('60 Elements'!E$2:E$61="—",ROW('60 Elements'!E$2:E$61)),8)),"")} | B38: {=IFERROR(INDEX('60 Elements'!C:C,SMALL(IF('60 Elements'!E$2:E$61="—",ROW('60 Elements'!E$2:E$61)),8)),"")} | C38: {=IFERROR(INDEX('60 Elements'!D:D,SMALL(IF('60 Elements'!E$2:E$61="—",ROW('60 Elements'!E$2:E$61)),8)),"")} | D38: {=IFERROR(INDEX('60 Elements'!F:F,SMALL(IF('60 Elements'!E$2:E$61="—",ROW('60 Elements'!E$2:E$61)),8)),"")} | E38: {=IFERROR(INDEX('60 Elements'!E:E,SMALL(IF('60 Elements'!E$2:E$61="—",ROW('60 Elements'!E$2:E$61)),8)),"")} | F38: {=IFERROR(SMALL(IF('60 Elements'!E$2:E$61="—",ROW('60 Elements'!E$2:E$61)-ROW('60 Elements'!E$2)+2),8),"")}
A39: {=IFERROR(INDEX('60 Elements'!B:B,SMALL(IF('60 Elements'!E$2:E$61="—",ROW('60 Elements'!E$2:E$61)),9)),"")} | B39: {=IFERROR(INDEX('60 Elements'!C:C,SMALL(IF('60 Elements'!E$2:E$61="—",ROW('60 Elements'!E$2:E$61)),9)),"")} | C39: {=IFERROR(INDEX('60 Elements'!D:D,SMALL(IF('60 Elements'!E$2:E$61="—",ROW('60 Elements'!E$2:E$61)),9)),"")} | D39: {=IFERROR(INDEX('60 Elements'!F:F,SMALL(IF('60 Elements'!E$2:E$61="—",ROW('60 Elements'!E$2:E$61)),9)),"")} | E39: {=IFERROR(INDEX('60 Elements'!E:E,SMALL(IF('60 Elements'!E$2:E$61="—",ROW('60 Elements'!E$2:E$61)),9)),"")} | F39: {=IFERROR(SMALL(IF('60 Elements'!E$2:E$61="—",ROW('60 Elements'!E$2:E$61)-ROW('60 Elements'!E$2)+2),9),"")}
A40: {=IFERROR(INDEX('60 Elements'!B:B,SMALL(IF('60 Elements'!E$2:E$61="—",ROW('60 Elements'!E$2:E$61)),10)),"")} | B40: {=IFERROR(INDEX('60 Elements'!C:C,SMALL(IF('60 Elements'!E$2:E$61="—",ROW('60 Elements'!E$2:E$61)),10)),"")} | C40: {=IFERROR(INDEX('60 Elements'!D:D,SMALL(IF('60 Elements'!E$2:E$61="—",ROW('60 Elements'!E$2:E$61)),10)),"")} | D40: {=IFERROR(INDEX('60 Elements'!F:F,SMALL(IF('60 Elements'!E$2:E$61="—",ROW('60 Elements'!E$2:E$61)),10)),"")} | E40: {=IFERROR(INDEX('60 Elements'!E:E,SMALL(IF('60 Elements'!E$2:E$61="—",ROW('60 Elements'!E$2:E$61)),10)),"")} | F40: {=IFERROR(SMALL(IF('60 Elements'!E$2:E$61="—",ROW('60 Elements'!E$2:E$61)-ROW('60 Elements'!E$2)+2),10),"")}
A41: {=IFERROR(INDEX('60 Elements'!B:B,SMALL(IF('60 Elements'!E$2:E$61="—",ROW('60 Elements'!E$2:E$61)),11)),"")} | B41: {=IFERROR(INDEX('60 Elements'!C:C,SMALL(IF('60 Elements'!E$2:E$61="—",ROW('60 Elements'!E$2:E$61)),11)),"")} | C41: {=IFERROR(INDEX('60 Elements'!D:D,SMALL(IF('60 Elements'!E$2:E$61="—",ROW('60 Elements'!E$2:E$61)),11)),"")} | D41: {=IFERROR(INDEX('60 Elements'!F:F,SMALL(IF('60 Elements'!E$2:E$61="—",ROW('60 Elements'!E$2:E$61)),11)),"")} | E41: {=IFERROR(INDEX('60 Elements'!E:E,SMALL(IF('60 Elements'!E$2:E$61="—",ROW('60 Elements'!E$2:E$61)),11)),"")} | F41: {=IFERROR(SMALL(IF('60 Elements'!E$2:E$61="—",ROW('60 Elements'!E$2:E$61)-ROW('60 Elements'!E$2)+2),11),"")}
A42: {=IFERROR(INDEX('60 Elements'!B:B,SMALL(IF('60 Elements'!E$2:E$61="—",ROW('60 Elements'!E$2:E$61)),12)),"")} | B42: {=IFERROR(INDEX('60 Elements'!C:C,SMALL(IF('60 Elements'!E$2:E$61="—",ROW('60 Elements'!E$2:E$61)),12)),"")} | C42: {=IFERROR(INDEX('60 Elements'!D:D,SMALL(IF('60 Elements'!E$2:E$61="—",ROW('60 Elements'!E$2:E$61)),12)),"")} | D42: {=IFERROR(INDEX('60 Elements'!F:F,SMALL(IF('60 Elements'!E$2:E$61="—",ROW('60 Elements'!E$2:E$61)),12)),"")} | E42: {=IFERROR(INDEX('60 Elements'!E:E,SMALL(IF('60 Elements'!E$2:E$61="—",ROW('60 Elements'!E$2:E$61)),12)),"")} | F42: {=IFERROR(SMALL(IF('60 Elements'!E$2:E$61="—",ROW('60 Elements'!E$2:E$61)-ROW('60 Elements'!E$2)+2),12),"")}
A43: {=IFERROR(INDEX('60 Elements'!B:B,SMALL(IF('60 Elements'!E$2:E$61="—",ROW('60 Elements'!E$2:E$61)),13)),"")} | B43: {=IFERROR(INDEX('60 Elements'!C:C,SMALL(IF('60 Elements'!E$2:E$61="—",ROW('60 Elements'!E$2:E$61)),13)),"")} | C43: {=IFERROR(INDEX('60 Elements'!D:D,SMALL(IF('60 Elements'!E$2:E$61="—",ROW('60 Elements'!E$2:E$61)),13)),"")} | D43: {=IFERROR(INDEX('60 Elements'!F:F,SMALL(IF('60 Elements'!E$2:E$61="—",ROW('60 Elements'!E$2:E$61)),13)),"")} | E43: {=IFERROR(INDEX('60 Elements'!E:E,SMALL(IF('60 Elements'!E$2:E$61="—",ROW('60 Elements'!E$2:E$61)),13)),"")} | F43: {=IFERROR(SMALL(IF('60 Elements'!E$2:E$61="—",ROW('60 Elements'!E$2:E$61)-ROW('60 Elements'!E$2)+2),13),"")}
...

Sheet 60 Elements
A1: Face # | B1: Face Name | C1: Element | D1: Check Description | E1: Status | F1: Evidence / Notes | G1: Last Checked | H1: Deimantas Notes 04/23/2026
A2: 1 | B2: Survival | C2: Earth | D2: Syntax validation — node --check on every changed .js file | E2: PASS | F2: node --check: 7 key files OK (main, Face, TuningConfig, spectral, breath, phi-harmonics) | G2: 2026-04-11 | H2: Expand with specialized spirals! More matrixes!
A3: 1 | B3: Survival | C3: Water | D3: No crashes — POC loads in browser without console errors | E3: —
A4: 1 | B4: Survival | C4: Fire | D4: Script & dependency order — spectral/breath analyzers before main.js | E4: —
A5: 1 | B5: Survival | C5: Air | D5: Environment compatibility — Windows path separators, pwsh vs bash | E5: PASS | F5: Windows paths handled, pwsh used | G5: 2026-04-11
A6: 1 | B6: Survival | C6: Ether | D6: Import resolution — ES module imports, cache-busting ?v= strings | E6: —
A7: 2 | B7: Foundation | C7: Earth | D7: Variable shadowing — locals shadowing outer scope (caused real bugs) | E7: —
A8: 2 | B8: Foundation | C8: Water | D8: PhiHarmonics constants — no hardcoded 0.618, 0.382, 1.618 etc. | E8: PASS | F8: All phi values in comments only, not hardcoded in executable code | G8: 2026-04-11
A9: 2 | B9: Foundation | C9: Fire | D9: Export contracts — window globals: Quannex, PhiHarmonics, Logger etc. | E9: PASS | F9: window.Quannex, PhiHarmonics, Logger globals documented in main.js | G9: 2026-04-11
A10: 2 | B10: Foundation | C10: Air | D10: Type safety — face IDs numbers (1-12), energy 0-1, NaN guards | E10: —
A11: 2 | B11: Foundation | C11: Ether | D11: Import hygiene — unused imports removed, no side-effect-only imports | E11: —
A12: 3 | B12: Clarity | C12: Earth | D12: "Why" comments — Greek params (α-θ) documented, phi powers explained | E12: WARN | F12: Doc-drift class found 2026-04-07; SSOT lookup rule established | G12: 2026-04-07
A13: 3 | B13: Clarity | C13: Water | D13: Architecture docs — FILE_STRUCTURE_MAP, MODULE_ARCHITECTURE current | E13: PASS | F13: DOCUMENTATION_INDEX.md current, FILE_STRUCTURE_MAP exists | G13: 2026-03-14
A14: 3 | B14: Clarity | C14: Fire | D14: Debug trails — symptom → root cause → fix documented | E14: PASS | F14: Debug trail documented in LEARNINGS.md + session contexts | G14: 2026-04-07
A15: 3 | B15: Clarity | C15: Air | D15: Calculation audit trail — every formula traceable input→formula→output | E15: PASS | F15: CALCULATION_AUDIT_TRAIL.md: 28KB, every formula traced | G15: 2026-04-11
A16: 3 | B16: Clarity | C16: Ether | D16: Cross-workspace notes — thesis-relevant evidence flagged | E16: PASS | F16: CrossWorkspaceUpdate pattern active, /thesis skill exists | G16: 2026-04-07
A17: 4 | B17: Harmony | C17: Earth | D17: Deduplication — 3 spectral analyzer files consistent | E17: WARN | F17: 3 spectral analyzer files still exist (known tech debt) | G17: 2026-03-14
A18: 4 | B18: Harmony | C18: Water | D18: Dead code removal — no commented-out code, use archive/ dir | E18: PASS | F18: No commented-out code in core files; archive/ dir exists | G18: 2026-03-14
A19: 4 | B19: Harmony | C19: Fire | D19: Naming conventions — camelCase vars, PascalCase classes, kebab files | E19: —
A20: 4 | B20: Harmony | C20: Air | D20: Anti-pattern cleanup — Logger.* not console.log, null checks on DOM | E20: PASS | F20: Zero raw console.log in core/advanced/main — all Logger.* | G20: 2026-04-11
A21: 4 | B21: Harmony | C21: Ether | D21: File organization — JS in correct subdirectory, pages in pages/ | E21: PASS | F21: JS in correct subdirs, pages in pages/ | G21: 2026-04-11
A22: 5 | B22: Signal | C22: Earth | D22: Test honesty — no try/catch swallowing failures in tests | E22: PASS | F22: Stress test honesty verified Feb 2026 (was once dishonest) | G22: 2026-02-08
A23: 5 | B23: Signal | C23: Water | D23: Error message accuracy — Logger.warn/error describe actual problem | E23: —
A24: 5 | B24: Signal | C24: Fire | D24: Logging consistency — all through Logger.*, correct severity levels | E24: PASS | F24: Full Logger.* migration done (930f687) | G24: 2026-03-14
A25: 5 | B25: Signal | C25: Air | D25: Data validation — data-validator catches corruption patterns | E25: PASS | F25: data-validator.js: 82 tests green | G25: 2026-04-11
A26: 5 | B26: Signal | C26: Ether | D26: No silent failures — edge cases produce warnings, not wrong answers | E26: —
A27: 6 | B27: Consciousness | C27: Earth | D27: AI navigability — new Claude session orients in <30 seconds | E27: PASS | F27: CLAUDE.md + DOCUMENTATION_INDEX + hooks active | G27: 2026-04-07
A28: 6 | B28: Consciousness | C28: Water | D28: Human readability — phi ratios explained, metaphor accessible | E28: —
A29: 6 | B29: Consciousness | C29: Fire | D29: Dependency maps — loader→data→engine→analysis chain discoverable | E29: —
A30: 6 | B30: Consciousness | C30: Air | D30: Entry points marked — orchestrator, demo, pages, engine API documented | E30: PASS | F30: 4 entry points documented in CLAUDE.md | G30: 2026-04-07
A31: 6 | B31: Consciousness | C31: Ether | D31: Session context — hooks provide context, memory MCP populated | E31: PASS | F31: session-start hook, pre-compact hook, memory MCP populated | G31: 2026-04-07
A32: 7 | B32: Coherence | C32: Earth | D32: Engine patterns — follows 5-pass calculation pattern in main.js | E32: PASS | F32: 5-pass pipeline intact in main.js | G32: 2026-04-07
A33: 7 | B33: Coherence | C33: Water | D33: Constant usage — PhiHarmonics for thresholds, TuningConfig for params | E33: PASS | F33: TuningConfig.js SSOT, PhiHarmonics for thresholds | G33: 2026-04-07
A34: 7 | B34: Coherence | C34: Fire | D34: Analyzer structure — class with analyze() method, structured results | E34: —
A35: 7 | B35: Coherence | C35: Air | D35: Sacred geometry respect — faces/edges/vertices vocabulary, not generic | E35: PASS | F35: Sacred geometry vocabulary used consistently | G35: 2026-04-11
A36: 7 | B36: Coherence | C36: Ether | D36: Data format consistency — company templates follow quannex/ format | E36: PASS | F36: 4 company templates follow quannex/ format | G36: 2026-04-11
A37: 8 | B37: Resilience | C37: Earth | D37: Edge cases — 0-energy faces, missing KPI data, NaN propagation | E37: WARN | F37: Edge cases not re-tested since Feb 2026 | G37: 2026-02-08
A38: 8 | B38: Resilience | C38: Water | D38: Stress testing — all 4 templates, rapid updateKPI() calls | E38: —
A39: 8 | B39: Resilience | C39: Fire | D39: Security — CSV injection safe, sessionStorage validated, no path traversal | E39: —
A40: 8 | B40: Resilience | C40: Air | D40: Failure mode simulation — missing files, malformed JSON, full storage | E40: —
...

Sheet Test Tracker
A1: Suite | B1: File Path | C1: Expected | D1: Actual | E1: Pass | F1: Fail | G1: Last Run | H1: Notes
A2: Phi Math Constants | B2: tests/phi-math.test.js | C2: 127 | D2: 127 | E2: 127 | F2: 0 | G2: 2026-04-11
A3: Integration (Engine) | B3: tests/integration.test.mjs | C3: 55 | D3: 55 | E3: 55 | F3: 0 | G3: 2026-04-11 | H3: MODULE_TYPELESS warning (cosmetic)
A4: Excel Parser Round-Trip | B4: tests/excel-parser.test.mjs | C4: 42 | D4: 42 | E4: 42 | F4: 0 | G4: 2026-04-11
A5: Data Validator | B5: tests/data-validator.test.mjs | C5: 82 | D5: 82 | E5: 82 | F5: 0 | G5: 2026-04-11 | H5: Was 88 in some old docs — 82 is the real count
A6: Browser Smoke Test | B6: tests/smoke-test.mjs | C6: 77 | D6: — | E6: — | F6: — | G6: — | H6: Needs HTTP server on localhost:8000
A8: TOTAL | C8: =SUM(C2:C6) | D8: =SUM(D2:D6) | E8: =SUM(E2:E6) | F8: =SUM(F2:F6) | G8: 2026-04-11 | H8: Smoke test not included (needs server)
A10: HTML Browser Tests (manual, open in browser)
A11: Circuit Breaker | B11: tests/circuit-breaker.test.html | C11: — | D11: — | E11: — | F11: — | G11: — | H11: Needs browser
A12: KPI Constants Integrity | B12: tests/kpi-constants-integrity.test.html | C12: — | D12: — | E12: — | F12: — | G12: — | H12: Needs browser
A13: Phase 3 Integrity | B13: tests/phase3-integrity-tests.html | C13: — | D13: — | E13: — | F13: — | G13: — | H13: Needs browser
A15: How to run: node tests/run-all.js (for smoke test: first run python -m http.server 8000)
A16: 2026-05-25 | B16: POC Test Suite v1.0 — ship-it baseline | C16: 536/536 PASSING | D16: Integration 55 + Excel Parser 42 + Data Validator 82 + Still-Point 57 + AAG 13 + AvG 40 + Engine State Canonicality 55 + Spectral 18 + Edge Adv 18 + Vertex Adv 29 + PHI Math 127 = 536 | E16: Zero regression across 24 commits in 5-day arc · ship-v1.0 plan §14.B close · Added by POC W4.4 §31 cross-workspace tracker hygiene
A17: 2026-05-25 FINAL | B17: POC Test Suite v1.0 SHIP — full incl. Browser Smoke | C17: 613/613 PASSING (HTTP server up) | D17: PHI Math 127 + Integration 55 + Excel Parser 42 + Data Validator 82 + Still-Point 57 + AAG 13 + AvG 40 + Engine State Canonicality 55 + Spectral 18 + Edge Adv 18 + Vertex Adv 29 + Browser Smoke 77 = 613 | E17: 536/613 split: 536 unit-only when no HTTP server; +77 Browser Smoke when HTTP server up. Both numbers valid in their context · Sub-Arc 3 W4.6 hygiene clarification

Sheet Thesis Evidence
A1: POC → THESIS EVIDENCE MAP | H1: DEIMANTAS NOTES | I1: SCOPE SUMMARY | J1: IFC BACHELOR?
I2: =COUNTIF(I4:I13,"Bachelor")&" Bach · "&COUNTIF(I4:I13,"Master")&" MSc · "&COUNTIF(I4:I13,"PhD")&" PhD"
A3: POC Artifact | B3: File Path | C3: Size | D3: Status | E3: Target Chapter | F3: Integration Status | G3: Notes | H3: Deimantas Notes | I3: Scope Level | J3: In-scope for IFC?
A4: Spectral Analysis Chapter | B4: docs/thesis/SPECTRAL_ANALYSIS_CHAPTER.md | C4: 36 KB | D4: READY | E4: Ch4/5 Results | F4: Not yet integrated | G4: Formatted for .docx import | H4: If I Understand correctly, spectral analysis chapter is fall out of scope for my IFC bachelor thesis. It's probably, master's or PHD material. I want a bachelor, master, PHD spliting logic here in this whole sheet I think | I4: PhD | J4: =IF(I4="Bachelor","✅ In scope",IF(I4="Master","⚠️ Stretch","🛑 Out of scope"))
A5: Consciousness Model | B5: docs/thesis/CONSCIOUSNESS_MODEL.md | C5: 12 KB | D5: READY | E5: Ch2/3 Literature | F5: Not yet integrated | G5: 7 octaves + psychology basis | I5: Bachelor | J5: =IF(I5="Bachelor","✅ In scope",IF(I5="Master","⚠️ Stretch","🛑 Out of scope"))
A6: Defense Preparation | B6: docs/thesis/DEFENSE_PREPARATION.md | C6: 30 KB | D6: READY | E6: Defense prep (study guide) | F6: N/A | G6: Committee Q&A, 499 lines | I6: Bachelor | J6: =IF(I6="Bachelor","✅ In scope",IF(I6="Master","⚠️ Stretch","🛑 Out of scope"))
A7: Emergent Mathematical Truths | B7: docs/thesis/EMERGENT_MATHEMATICAL_TRUTHS.md | C7: 50 KB | D7: READY | E7: Ch4 Discussion | F7: Not yet integrated | G7: 11 discoveries, stress test evidence | I7: Master | J7: =IF(I7="Bachelor","✅ In scope",IF(I7="Master","⚠️ Stretch","🛑 Out of scope"))
A8: Novel Mathematical Contributions | B8: docs/thesis/NOVEL_MATHEMATICAL_CONTRIBUTIONS.md | C8: 36 KB | D8: READY | E8: Ch4 Appendix | F8: Not yet integrated | G8: 4 frameworks, ALCOA+ rigor | I8: Master | J8: =IF(I8="Bachelor","✅ In scope",IF(I8="Master","⚠️ Stretch","🛑 Out of scope"))
A9: Wisdom Brief | B9: docs/thesis/WISDOM_BRIEF.md | C9: 17 KB | D9: READY | E9: Ch2 Literature | F9: Not yet integrated | G9: Philosophical grounding | I9: Bachelor | J9: =IF(I9="Bachelor","✅ In scope",IF(I9="Master","⚠️ Stretch","🛑 Out of scope"))
A10: Calculation Audit Trail | B10: docs/math/CALCULATION_AUDIT_TRAIL.md | C10: 28 KB | D10: READY | E10: Appendix | F10: Not yet integrated | G10: "Academic armor" — every formula traced | I10: Bachelor | J10: =IF(I10="Bachelor","✅ In scope",IF(I10="Master","⚠️ Stretch","🛑 Out of scope"))
A11: Sacred Geometry Proof | B11: docs/math/SACRED_GEOMETRY_PROOF.md | C11: 31 KB | D11: READY | E11: Ch2/Appendix | F11: Not yet integrated | G11: Eigenvalue verification, phi proofs | I11: Master | J11: =IF(I11="Bachelor","✅ In scope",IF(I11="Master","⚠️ Stretch","🛑 Out of scope"))
A12: Spectral Implementation | B12: docs/math/SPECTRAL_IMPLEMENTATION.md | C12: 8 KB | D12: READY | E12: Ch4 Methods | F12: Not yet integrated | G12: Graph Laplacian → code mapping | I12: PhD | J12: =IF(I12="Bachelor","✅ In scope",IF(I12="Master","⚠️ Stretch","🛑 Out of scope"))
A13: Thesis Audit Report | B13: THESIS_AUDIT_REPORT.md | C13: 25 KB | D13: READY | E13: Reference only | F13: N/A | G13: VERDICT: PRISTINE, zero findings | I13: Bachelor | J13: =IF(I13="Bachelor","✅ In scope",IF(I13="Master","⚠️ Stretch","🛑 Out of scope"))
A16: CRITICAL TIMELINE
A17: Date | B17: Milestone | C17: Notes
A18: April 14 (DONE) | B18: CEN Phase 2 scoring — COMPLETE (session 25, Apr 7) | C18: BSC comparison 5/6. Evidence package ready.
A19: April 15-30 | B19: Validation session with CEN
A20: May 1-20 | B20: Write Chapters 5-7 (Case Study B, Cross-Case, Conclusions) | C20: PRIMARY WRITING WINDOW
A21: May 25 | B21: Final review pass
A22: June 1 (noon) | B22: HARD DEADLINE — upload to Onstage | C22: NON-NEGOTIABLE
A24: Spiral Octave Songbook Phase 4 Commitment | B24: SQ5 quantitative KPI embedding proof + paradigm reframe | C24: 2026-04-15 | D24: POC/deliverables/ + POC/docs/ | E24: Committee-reproducible | F24: Methodology + 5 worked examples + spiral 9.25/10 | G24: See SPIRAL_OCTAVE_SONGBOOK_SPEC.md
A25: ACTIVE BLOCKERS
A26: IFC language reframe (Ch2-5) | B26: Blocked on Jan Willem confirmation
A27: Breath Axes scoring + POC run | B27: Needed for Chapter 5 §5.1.3
A28: CEN Spiral Dashboard SSOT v1.0 | B28: Thesis defense centerpiece artifact | C28: Final Thesis/Thesis Work/Quannex Business Exports/CEN_Spiral_Dashboard_SSOT_v1.0_2026-05-22.xlsx + 2026-05-25.pdf + README.md | D28: 8 thesis-defense centerpieces · 22 sheets · 36 architectural locks · Wave 3 zero Critical · Lock #8.35 κ=φ² geometric derivation (B3 win) | E28: 2026-05-25 SHIPPED

Sheet Codebase Inventory
A1: Module | B1: Directory | C1: Files | D1: Key Components | E1: Status | F1: Notes | G1: Computed LOC | H1: Last Modified | I1: Tests Linked | J1: Last Reviewed | K1: Manifest
A2: Core Engine | B2: js/core/ | C2: 6 | D2: Face.js, TuningConfig.js, KPI.js | E2: Healthy | F2: SSOT for Greek constants (α-θ) | G2: 1804 | H2: 2026-04-18T06:10:01+00:00 | I2: — | J2: 2026-04-16 | K2: docs/modules/core.md
A3: Main Engine | B3: js/main.js | C3: 1 | D3: 1917-line calculation engine (5-pass) | E3: Healthy | F3: Consider extracting to js/core/ | G3: 1711 | H3: 2026-03-21T19:12:01+00:00 | I3: integration | J3: 2026-04-18 | K3: docs/modules/main.md
A4: Advanced Analysis | B4: js/advanced/ | C4: 9 | D4: spectral-analyzer, edge-analyzer, vertex-analyzer | E4: Healthy | F4: 3 spectral files = unification debt | G4: 4414 | H4: 2026-03-21T18:36:33+00:00 | I4: — | J4: 2026-04-18 | K4: docs/modules/advanced.md
A5: Constants | B5: js/constants/ | C5: 9 | D5: phi-harmonics.js, sacred-inquiry.js | E5: Healthy | F5: SSOT for phi-derived values | G5: 4475 | H5: 2026-03-21T19:11:41+00:00 | I5: integration, phi-math | J5: 2026-04-18 | K5: docs/modules/constants.md
A6: Data System | B6: js/data-system/ | C6: 13 | D6: data-validator.js, unified-data-loader.js | E6: Healthy | G6: 5144 | H6: 2026-03-21T19:12:50+00:00 | I6: data-validator | J6: 2026-04-18 | K6: docs/modules/data-system.md
A7: Simulator | B7: js/simulator/ | C7: 9 | D7: sim-*.js modules | E7: Healthy | F7: Gold-documented (Feb 8) | G7: 2094 | H7: 2026-02-08T11:12:36+00:00 | I7: — | J7: 2026-04-18 | K7: docs/modules/simulator.md
A8: Edge System | B8: js/edge/ | C8: 3 | D8: unified-edge.js, edge-manager.js | E8: Healthy | F8: Pure Membrane Model | G8: 1013 | H8: 2026-01-27T11:13:14+00:00 | I8: — | J8: 2026-04-18 | K8: docs/modules/edge.md
A9: Shadow System | B9: js/shadow/ | C9: 14 | D9: Shadow detection + generation | E9: Healthy | F9: AI-integrated | G9: 6102 | H9: 2026-03-10T20:02:37+00:00 | I9: — | J9: 2026-04-18 | K9: docs/modules/shadow.md
A10: Orchestrator | B10: js/orchestrator/ | C10: 24 | D10: 5-step wizard flow | E10: Healthy | F10: Has archive/ subdir | G10: 9221 | H10: 2026-03-21T19:08:43+00:00 | I10: — | J10: 2026-04-18 | K10: docs/modules/orchestrator.md
A11: AI Layer | B11: js/ai/ | C11: 37 | D11: Gemini integration, mapping context | E11: Healthy | G11: 14557 | H11: 2026-03-10T20:02:33+00:00 | I11: — | J11: 2026-04-18 | K11: docs/modules/ai.md
A12: Pages | B12: pages/ | C12: 9 | D12: HTML entry points + orchestrator | E12: Healthy | G12: 5460 | H12: 2026-03-21T19:05:30+00:00 | I12: — | J12: 2026-04-18 | K12: docs/modules/pages.md
A13: Tests | B13: tests/ | C13: 15 | D13: 5 suites + HTML tests | E13: 306/306 green | F13: See Test Tracker sheet | G13: 3716 | H13: 2026-04-18T06:19:47+00:00 | I13: — | J13: 2026-04-18 | K13: docs/modules/tests.md
A14: Companies | B14: companies/ | C14: 10 | D14: quannex, nova-tech, apex, zenith | E14: Healthy | F14: Each: json + csv + mapping | G14: 1999 | H14: 2026-04-11T16:19:29+00:00 | I14: — | J14: 2026-04-18 | K14: docs/modules/companies.md
A15: Documentation | B15: docs/ | C15: 73 | D15: thesis/, math/, edge/, archive/ | E15: WARN | F15: 13 growth ideas from Feb 16 audit | G15: 22211 | H15: 2026-04-18T11:24:20+00:00 | I15: — | J15: 2026-04-18 | K15: docs/modules/documentation.md
A16: Math Docs | B16: math/ | C16: 6 | D16: PENTAGRAM_ANALYSIS, OCTAVE_FRAMEWORK | E16: Healthy | F16: Standalone math references | G16: 1952 | H16: 2026-04-07T08:25:28+00:00 | I16: — | J16: 2026-04-18 | K16: docs/modules/math-docs.md
A18: Songbook Generator | B18: scripts/ | C18: 1 | D18: _build_songbook_phase4_commitment.py | E18: Healthy | F18: openpyxl, 7-sheet xlsx builder
A19: REFRENCE_MODELS Extractor | B19: scripts/ | C19: 1 | D19: _extract_refrence_models.py | E19: Healthy | F19: 420 cells -> JSON
A20: Command Center Patch | B20: scripts/ | C20: 1 | D20: _update_command_center_phase4.py | E20: Healthy | F20: This script
A21: KPI Database Patcher | B21: scripts/ | C21: 1 | D21: _patch_kpi_database_facenames.py | E21: Healthy | F21: faceName harmonization
A22: Songbook Spec | B22: docs/ | C22: 1 | D22: SPIRAL_OCTAVE_SONGBOOK_SPEC.md | E22: Healthy | F22: Canonical methodology spec v1.0
A23: TOTALS: 195 JS files | 9 pages | 4 company templates | 57 docs | 6 math docs | 306 automated tests

Sheet Session Log
A1: Date | B1: Focus | C1: Key Changes | D1: Commits | E1: Tests | F1: Spiral Verdict | G1: Thesis Impact | I1: SESSION CADENCE | L1: Date | M1: Session # | N1: Cumulative Sessions
A2: 46123 | B2: Control Panel | C2: Created CONTROL_PANEL.xlsx, verified 60 elements | D2: — | E2: 306/306 | F2: — | G2: Tracking artifact created | I2: Total sessions | J2: =COUNTA(A2:A25) | L2: 46053 | M2: 1 | N2: 1
A3: 46119 | B3: alpha-drift fix + Spiral Loop | C3: Patched 5 doc files, installed spiral refinement | D3: e8e99d1 | E3: 306/306 | F3: CLEAN | G3: Doc-drift class documented | I3: Last session | J3: =TEXT(MAX(A2:A25),"MMM D, YYYY") | L3: 46054 | M3: 1 | N3: 2
A4: 46095 | B4: Spectral eigenvalue fix | C4: Corrected Laplacian topology across 3 analyzers | D4: 7019657 | E4: — | F4: — | G4: Spectral chapter updated | I4: Days since last | J4: =TODAY()-MAX(A2:A25) | L4: 46061 | M4: 1 | N4: 3
A5: 46095 | B5: Sensitivity matrix | C5: Multi-mode sensitivity, KPI sensitivity analysis | D5: 6f0ccad | E5: — | F5: — | I5: Avg gap (days) | J5: =IFERROR(ROUND((MAX(A2:A25)-MIN(A2:A25))/(COUNTA(A2:A25)-1),1),"—") | L5: 46069 | M5: 1 | N5: 4
A6: 46069 | B6: Documentation audit | C6: 5-agent parallel audit, 8 priority actions done | D6: — | E6: — | F6: — | G6: Audit tracker created | I6: Days to defense | J6: =DATE(2026,6,1)-TODAY() | L6: 46095 | M6: 1 | N6: 5
A7: 46061 | B7: Stress test + simulator | C7: Full vision coherence simulator, honest stress report | D7: 9106dbf | E7: — | F7: — | G7: 11 emergent truths discovered | I7: Sessions needed (est.) | J7: =IFERROR(ROUND((DATE(2026,6,1)-TODAY())/J5,0),"—") | L7: 46095 | M7: 1 | N7: 6
A8: 46054 | B8: Thesis audit | C8: Complete thesis readiness audit | D8: — | E8: — | F8: — | G8: VERDICT: PRISTINE | L8: 46119 | M8: 1 | N8: 7
A9: 46053 | B9: Vertex topology fix | C9: Unified vertex topology across codebase | D9: 22db8cd | E9: — | F9: — | L9: 46123 | M9: 1 | N9: 8
A10: 46127 | B10: 420 Spiral Octave Songbook - Phase 4 Commitment Artifact | C10: 5 artifacts: xlsx, spec, command-center patch, JSON faceName patch, spiral report. Built from REFRENCE_MODELS extraction (420 cells). | D10: TBD | E10: smoke test PASS; no JS/engine tests touched | F10: RADIANT 9.25/10 (12/12 faces >= 9) | G10: SQ5 evidence; paradigm reframe: measure-what-is -> ask-what-is-alive | L10: 46127 | M10: 1 | N10: 9
A11: 46146 | B11: CEN Coherence Assessment Form architect spec (s41ct continuation) | C11: Architecture sketch (~5,500w) + Wireframe (~3,200w) + Spiral report; Final Thesis Ch7 R22 prose drafted | D11: - | E11: - | F11: 9.35/10 (triad) | G11: Ch7 R22 future-research recommendation drafted; application deferred to Ch7 R1 hardening pass
A26: HOW TO USE: After each session, add one row. Date + Focus + Key Changes are the minimum. Run tests and record. Spiral Verdict from /selfcritique.
A27: 2026-04-24 | B27: Cross-Workspace from BDQ-5 (Songbook + 60-element + Cloud Form) | C27: BDQ adopted POC Songbook paradigm as canonical; created 60-element rubric skeleton referencing POC 420 grid; Schema B canonicalized for breath axes (check js/main.js); Cloud Form v1 spec (609 lines) + Question Bank (1293 lines) drafted; Wk6-Wk7 longitudinal data available | D27: - | E27: - | F27: RADIANT (BDQ-side, see mirror) | G27: Ch5 cross-case continuity; Songbook propagated cleanly; Wk6 and Wk7 data available for Ch5 Table 5.4 update
A28: 2026-05-11 | B28: Cross-Workspace from Final Thesis s50 (Songbook Academic Pass) | C28: POC_420_Songbook_Thesis_Master_v3.0_AcademicPass_2026-05-11.xlsx shipped (18 sheets; 4 academic-pass dimensions; honest 9.46/10 RADIANT). CEN-facing derivative CEN_420_Songbook_v0.1 also shipped (9 sheets; honest 9.34/10). Source v2.1 SHA d35d8e64 preserved unchanged. | D28: - | E28: - | F28: RADIANT 9.46/10 (Workbook A) + 9.34/10 (Workbook B); see Final Thesis/Thesis Work/spiral-reports/ (both mirrored to POC/spiral-reports/) | G28: Thesis-defense surface (Sheet 21 CBI Defense maps Hanze B1-B6) + master's-thesis continuation seed (Sheet 20 §6.G + Sheet 19 §6 refs + §6.G.5 architectural seeds) preserved. | N28: Added by Final Thesis session 50 via Cross-Workspace Tracker Row Protocol (per ~/.claude/CLAUDE.md). Memory entity: CrossWorkspaceUpdate-Songbook-AcademicPass-v3.0-2026-05-11. FT mirror at Final Thesis/Thesis Work/Quannex Business Exports/ byte-equivalent SHA 81ffbcca...
A29: 2026-05-17 | B29: Cross-Workspace from Final Thesis s58-followup — Vortex topology canonical correction cascade | C29: Final Thesis s58-followup landed canonical vortex topology fix in SpiralDASHBOARD-Leading_V2 VORTEX_MAP (14 of 20 vertex face-triples were wrong; source-fixed). CEN MVF vortex cascade applied (phi-weighted vortexStrength formula = 0.618 x (sigma/0.577) + 0.382 x mean per POC March 2026 reconciliation; 6-state Dormant/Rising/Powerful Ascent/Declining/Critical Descent/Turbulent classification — NOT Wall/Gate/etc which apply only to edges). POC workspace may want to ingest source-fix when relevant. Spiral reports: Topology_Integrity_Audit_s58-followup_2026-05-17.md + POC_Vortex_Canonical_Verification_s58-followup_2026-05-17.md. Added by Final Thesis session s58-followup at 2026-05-17 via Cross-Workspace Tracker Row Protocol. | D29: - | E29: -
A30: 2026-05-25 | B30: ship-v1.0 plan §14.B close | C30: Sub-Arc 3 Wave 4 — verification + sign-off + distribution | D30: All 7 W4 steps closing (W4.1 validator 222→0 · W4.2 PDF brand 5/5 · W4.3 cross-workspace · W4.4 POC panel · W4.5 handoff · W4.6 spiral · W4.7 archive). 5-day arc 2026-05-21→2026-05-25 closes. 24 commits. 8 thesis-defense centerpieces. Trust-the-Geometry §6.6 named. | E30: v1.0 SHIPPED · 0 Critical · ALL PATHS CLOSED
A31: 2026-05-25 FINAL | B31: Sub-Arc 3 W4.6 hygiene close + Sheet 21 Coherence Story | C31: v1.0 FINAL ship-it: Sheet 21 narrative + Trust-the-Geometry §6.6 audit + Excel-clean | D31: 11+ pre-ship discrepancies surfaced + corrected (the methodology auditing itself). Sheet 21 Section B BSC-ID vs face-placement clarified. Validator regression-check targets updated κ=4 era→κ=φ² era. Excel formula errors 16→0 via Glossary leading-= fix + STDEV.P→STDEVP. | E31: v1.0 SHIPPED FINAL · 23 sheets · 613/613 tests · 0 Critical · ALL PATHS CLOSED · Sheet 21 marquee active

Sheet CEN Deliverables
A1: CEN PARTNERSHIP -- DELIVERABLES TRACKER
A2: Source: Partnership_Overview_and_FAQ.md (signed scope) | Path: Final Thesis/.../Coherence Partnership Quannex x CEN
A3: PHASE PROGRESS | B3: Ph0: Kickoff | C3: Ph1: Conv. Analysis | D3: Ph2: Scoring | E3: Ph3: Validation | F3: Ph4: Final Report | G3: ★ Apr 17 meeting | H3: =DATE(2026,4,17)-TODAY()&" day(s) away"
A4: PROMISED DELIVERABLES (from Partnership Overview & FAQ, signed Feb 2026)
A5: # | B5: Promised Deliverable | C5: Description | D5: Status | E5: Source Material | F5: Target Phase | G5: Packaged? | H5: Notes
A6: 1 | B6: Conventional strategic analysis | C6: PESTEL, Porter's 5 Forces, McKinsey 7S, SWOT, BSC mapping | D6: DONE | E6: CEN_Conventional_Analysis_Working_Draft.md (77KB) + PESTEL notes + 7S analysis | F6: Phase 1-2 | G6: NO | H6: Working draft exists in _Not yet facing/ folder. Post-interview enriched (session 18). Needs CEN-facing format.
A7: 2 | B7: Novel coherence assessment (Spiral Dashboard) | C7: Full coherence portrait using Spiral Dashboard methodology | D7: DONE | E7: Phase 2 Evidence Package (14 docs) — Vector Diagnostics, Breath, Divergence, BSC | F7: Phase 2-3 | G7: NO | H7: Core deliverable. Evidence complete, needs branded report.
A8: 3 | B8: 3D visualization of CEN's organizational DNA | C8: Interactive dodecahedron reflecting CEN's patterns | D8: REQUIRES CEN TEMPLATE | E8: POC codebase + CEN raw scores (normalized arrays ready in RawScores_Frozen.md) | F8: Phase 3 | G8: NO | H8: Need to create companies/cen/ template from Phase 2 scores. Then POC renders it live.
A9: 4 | B9: Shadow analysis | C9: Hidden tensions, blind spots, dormant strengths | D9: PARTIAL | E9: CEN_Phase2_C3_DivergenceNarratives.md covers divergence. Full shadow analysis needs POC run. | F9: Phase 3 | G9: NO | H9: Divergence narratives done. Full shadow detection requires CEN template in POC engine.
A10: 5 | B10: Breath analysis | C10: 6 polarity axes balance assessment | D10: DONE | E10: CEN_Phase2_C2_BreathAxes.md (21KB) + raw axis scores frozen | F10: Phase 2-3 | G10: NO | H10: Complete with 4-vector data. Needs formatting.
A11: 6 | B11: Debrief session | C11: Discussing findings, implications, actionable next steps | D11: UPCOMING | E11: Phase 3 validation meeting materials (to be prepared) | F11: Phase 3 | G11: NO | H11: ~April 17. Presentation + CEN-facing summary needed.
A12: 7 | B12: Proposed KPIs with methodology notes | C12: Tailored KPI suggestions for CEN's context | D12: IN PROGRESS | E12: Will derive from coherence portrait + face mapping + breath analysis | F12: Phase 3-4 | G12: NO | H12: Promised deliverable — not yet created. Should emerge from the coherence assessment. 2026-04-17: Phase 4 commitment artifact delivered (methodology + 5 worked examples). Full Songbook target May 2026.
A13: 8 | B13: Thesis acknowledgment | C13: Named acknowledgment in published thesis | D13: NOT STARTED | E13: Will be written in thesis Chapter 1 or Acknowledgments section | F13: Phase 4 | G13: NO | H13: Write during final thesis assembly (May).
A15: PHASE OVERVIEW
A16: Phase | B16: Activity | C16: Date Window | D16: Status | E16: Work Done? | F16: Packaged? | G16: Delivery Folder | H16: Notes
A17: Phase 0 | B17: Kickoff & orientation | C17: Late Feb | D17: DONE | E17: YES | F17: N/A | G17: N/A (meeting only) | H17: Feb 13 meeting. Signed NDA + Partnership. 3D demo shown.
A18: Phase 1 | B18: Conventional analysis + interview | C18: Mar 9-31 | D18: DONE | E18: YES | F18: NO | G18: Deliverables from Quannex/Phase 1 | H18: Interview Mar 20, synthesis 57KB. FOLDER EMPTY.
A19: Phase 2 | B19: Scoring + BSC comparison + evidence | C19: Apr 1-14 | D19: DONE | E19: YES | F19: NO | G19: Deliverables from Quannex/Phase 2 | H19: Both questionnaires Apr 7. 14-doc evidence package. BSC 5/6. FOLDER EMPTY.
A20: Phase 3 | B20: Results presentation + validation + debrief | C20: Apr 15-30 | D20: UPCOMING | E20: PARTIAL | F20: NO | G20: Deliverables from Quannex/Phase 3 | H20: ~April 17. Need: presentation, CEN summary, 3D demo (needs CEN template).
A21: Phase 4 | B21: Final report + KPIs + acknowledgment | C21: May | D21: NOT STARTED | E21: NO | F21: NO | G21: Deliverables from Quannex/Phase 4 | H21: Depends on Phase 3 validation + thesis chapters.
A23: PACKAGING ACTIONS — What needs to happen before Phase 3 (~April 17)
A24: Priority | B24: Action | C24: Source | D24: Output Format | E24: Destination | F24: Status | G24: Effort | H24: Notes
A25: CRITICAL | B25: Create CEN company template for POC | C25: RawScores_Frozen.md (normalized arrays ready) | D25: companies/cen/ (company.json + kpis.csv + mapping-context.json) | E25: POC/companies/cen/ | F25: NOT DONE | G25: ~2 hours | H25: Unlocks: 3D visualization (#3), shadow analysis (#4), live demo. D_norm + E_norm available. Use average or researcher-calibrated vector.
A26: CRITICAL | B26: Create Phase 3 validation presentation | C26: Phase 2 evidence package (C1-C4 docs) | D26: PPTX (Quannex branded) | E26: Deliverables/Phase 3/ | F26: NOT DONE | G26: ~3 hours | H26: The centerpiece of the ~April 17 meeting. Coherence portrait + key findings.
A27: CRITICAL | B27: Create CEN-facing coherence summary | C27: C1 Vector Diagnostics + C2 Breath + C3 Divergence | D27: PDF (Quannex branded, 2-4 pages) | E27: Deliverables/Phase 3/ | F27: NOT DONE | G27: ~2 hours | H27: Executive summary leave-behind document for D and E.
A28: HIGH | B28: Package Phase 1 deliverables | C28: Interview synthesis (57KB) + face mapping (33KB) | D28: PDF (Quannex branded) | E28: Deliverables/Phase 1/ | F28: NOT DONE | G28: ~1 hour | H28: Overdue (was due late March). Format existing MDs to branded PDFs.
A29: HIGH | B29: Package Phase 2 deliverables | C29: Evidence package C1-C4 + BSC comparison + breath analysis | D29: PDF (Quannex branded) | E29: Deliverables/Phase 2/ | F29: NOT DONE | G29: ~2 hours | H29: Overdue (was due early April). Format existing MDs to branded PDFs.
A30: HIGH | B30: Package conventional analysis | C30: CEN_Conventional_Analysis_Working_Draft.md (77KB) | D30: PDF (Quannex branded) | E30: Deliverables/Phase 1/ or Phase 2/ | F30: NOT DONE | G30: ~1 hour | H30: Promised deliverable #1. PESTEL + 7S + SWOT + BSC. Post-interview enriched.
A31: MEDIUM | B31: Prepare KPI proposals | C31: Derive from coherence portrait + face mapping | D31: PDF or section in final report | E31: Deliverables/Phase 3/ or Phase 4/ | F31: NOT STARTED | G31: ~2 hours | H31: Promised deliverable #7. Can be preliminary for Phase 3, finalized Phase 4.
A32: LOW | B32: Run CEN data through POC engine | C32: CEN company template (after creation) | D32: Screenshots + engine output for presentation | E32: Phase 3 presentation | F32: BLOCKED | G32: ~30 min | H32: Blocked on CEN template creation. Once created, engine runs automatically.
A34: CEN RAW SCORES (frozen Apr 8 — from RawScores_Frozen.md)
