Workbook
Name E_Vector: DODECA_ENGINE!$K$2:$K$13
Name Face_1: SYSTEM_COHERENCE!$B$2
Name Headline_KPI: Octave_1_KPIs[O1 - Survival (Focus: Existence)]
Name L_Matrix: DODECA_ENGINE!$A$16:$L$27
Name U_Matrix: DODECA_ENGINE!$A$31:$L$42

Sheet INTRO
A1: Header | B1: Explanation | C1: Your Quannex Data (Example) | Y1: That is the perfect and most practical question a founder can ask. It is the bridge between the grand, cosmic strategy and the "what do I actually do on Monday morning?" reality.
A2: KPI_ID | B2: A unique nickname for this measurement. | C2: F1.1
A3: KPI_Name | B3: What are we measuring? | C3: Months of Runway | Y3: You are asking the model to move from a strategic diagnosis to a tactical prescription. And while the answer is nuanced, it is incredibly powerful.
A4: Owner | B4: Who is responsible for this? | C4: Deimantas
A5: Department | B5: Which "hat" are you wearing for this? | C5: Finance | Y5: Let's be very clear:
A6: Primary_Octave | B6: Which "theme" does this belong to? | C6: O1 (Survival)
A7: Direction | B7: Is more better or less better? | C7: ↑ (More is better) | Y7: The dodecahedron cannot directly tell you, "Send 3 applications per week with a 10% success rate." Why? Because the model is a mirror of your internal coherence, not a crystal ball that can predict the external world's response (like a grant committee's decision).
A8: Weight | B8: How important is this stat right now? (from 0 to 1) | C8: 1.0 (Extremely important!)
A9: Unit | B9: What are we counting? | C9: Months | Y9: However—and this is the magical part—it can give you something even more powerful: a framework for setting that target yourself and then measuring its true impact on your entire system.
A10: Value | B10: What's the real number right now? Let's say you have €1200 saved and your monthly costs are €200. Value = 1200 / 200 = 6 months. | C10: 6
A11: Target_Ideal | B11: What's our dream goal? A safe, comfortable 12 months. | C11: 12 | Y11: Here is how we "metric-ize" the strategic mandate. We will use the concepts of Leading and Lagging Indicators within our dodecahedron framework.
A12: Target_Min | B12: What's the absolute danger zone? Less than 3 months of runway is very risky. | C12: 3
A13: K_Normalized | B13: The Excel formula that turns your numbers into a 0-1 score. | C13: =MAX(0, MIN(1, (C10-C12)/(C11-C12))) -> 0.33333333
Y15: Metric-izing the Mandate: A Practical Guide
Y17: Our Grand Strategic Mandate is to "FIX THE FOUNDATION," which is measured by the Emergent KPI: the Aspiration-Actuality Gap (AAG). Our goal is to raise the AAG score from 0.35 towards 1.0.
Y19: We know the highest-leverage way to do this is to increase the energy of the "Actuality" faces, especially F1: Financial Capital.
Y21: Now, let's break that down into a measurable action plan.
Y23: 1. Deconstruct the Goal into Lagging and Leading KPIs:
Y25: The Lagging Indicator (The Ultimate Result):
Y29: This is KRI F1.1: Months of Runway. This is the ultimate measure of success for our financial health. We cannot control it directly—it is the result of our actions. It is a "lagging" indicator because by the time it changes, the work is already done.
Y31: Our GOAL is to increase the Face Energy of F1.
Y33: The Leading Indicator (The Action We Can Control):
Y37: This is KPI F1.2: # of Funding Opportunities Pursued. This is the action. This is the work. We can directly control this number every single week. It is a "leading" indicator because we hypothesize that performing this action will eventually cause a change in the lagging indicator.
Y39: 2. Set an Initial, Hypothesis-Driven Target for Your Leading KPI:
Y41: This is where your human wisdom as the founder comes in. The math has told you what to do (Focus on Finance). Now, you must propose an initial hypothesis for how.
... Y69: This is not a simple, mechanical answer. It is the beginning of a living, intelligent, and deeply honest conversation between you and your startup, with the dashboard as the language that makes it possible.

Sheet BREATH_RATIOS
A1: Harmonic Pair: | B1: Side - Projection: | C1: Side - Reception: | D1: Archetype | E1: Component | F1: Face Energy | G1: Final BR* | H1: Status/Interpretation | K1: Purpose: To provide a high-level, strategic view of the six primary energetic balances within the organization. This sheet calculates the "inhale/exhale" dynamic for each of the six geometrically-defined harmonic pairs. It is the "macro-scope" that reveals the fundamental state of equilibrium or disequilibrium in the system, complementing the tactical, neighbor-to-neighbor view of the EDGE_TENSION_MAP.
A2: Pair 1 (F1 ↔ F11) | B2: Face 1 | C2: Face 11 | D2: Resource Flow Axis | E2: Projection (Exhale): Funding Pursuit | F2: =_xlfn.XLOOKUP(B2,DODECA_ENGINE!$A$2:$A$13,E_Vector) -> 0.23961225 | G2: =F3/F2 -> 0.51514525 | H2: =IF(G2>1.2,"Abundant Inhale",IF(G2<0.8,"Strong Exhale","Balanced")) -> Strong Exhale
E3: Reception (Inhale): Capital Held | F3: =_xlfn.XLOOKUP(C2,DODECA_ENGINE!$A$2:$A$13,E_Vector) -> 0.12343511 | K3: Pair 1 (Face 1 ↔ 11): Financial Capital ↔ Funding Pipeline (The "Resource Flow" Axis)
K4: Pair 2 (Face 2 ↔ 7): Intellectual Capital ↔ Brand & Reputation (The "Substance & Story" Axis)
A5: Pair 2 (F2 ↔ F7) | B5: Face 2 | C5: Face 7 | D5: Substance & Story Axis | E5: Projection (Exhale): Brand Projected | F5: =_xlfn.XLOOKUP(B5,DODECA_ENGINE!$A$2:$A$13,E_Vector) -> 0.40086372 | G5: =F6/F5 -> 0.51920437 | H5: =IF(G5>1.2, "Abundant Inhale", IF(G5<0.8, "Strong Exhale", "Balanced")) -> Strong Exhale | K5: Pair 3 (Face 3 ↔ 8): Human Capital ↔ Core Operations (The "Being & Doing" Axis)
E6: Reception (Inhale): IP Embodied | F6: =_xlfn.XLOOKUP(C5,DODECA_ENGINE!$A$2:$A$13,E_Vector) -> 0.2081302 | K6: Pair 4 (Face 4 ↔ 9): Structural Capital ↔ Regenerative Flow (The "Form & Integrity" Axis)
K7: Pair 5 (Face 5 ↔ 10): Market Resonance ↔ Foundational Values (The "Perception & Truth" Axis)
A8: Pair 3 (F3 ↔ F8) | B8: Face 3 | C8: Face 8 | D8: Being & Doing Axis | E8: Projection (Exhale): Operations Done | F8: =_xlfn.XLOOKUP(B8,DODECA_ENGINE!$A$2:$A$13,E_Vector) -> 0.16559188 | G8: =F9/F8 -> 1.3339496 | H8: =IF(G8>1.2, "Abundant Inhale", IF(G8<0.8, "Strong Exhale", "Balanced")) -> Abundant Inhale | K8: Pair 6 (Face 6 ↔ 12): Community & Partners ↔ Risk & Resilience (The "Network & Fortress" Axis)
E9: Reception (Inhale): Human Energy | F9: =_xlfn.XLOOKUP(C8,DODECA_ENGINE!$A$2:$A$13,E_Vector) -> 0.22089122
K10: A score above 1.2 suggests the organization is receiving/holding more energy than it is projecting/acting. A score below 0.8 suggests it is projecting/acting with more energy than it is receiving/regenerating.
A11: Pair 4 (F4 ↔ F9) | B11: Face 4 | C11: Face 9 | D11: Form & Integrity Axis | E11: Projection (Exhale): Structures Built | F11: =_xlfn.XLOOKUP(B11,DODECA_ENGINE!$A$2:$A$13,E_Vector) -> 0.2447884 | G11: =F12/F11 -> 1.790704 | H11: =IF(G11>1.2, "Abundant Inhale", IF(G11<0.8, "Strong Exhale", "Balanced")) -> Abundant Inhale
E12: Reception (Inhale): Regen. Flow | F12: =_xlfn.XLOOKUP(C11,DODECA_ENGINE!$A$2:$A$13,E_Vector) -> 0.43834356 | K12: Axis 1: The Resource Axis
K13: Projection Face: F11: Funding Pipeline (The act of seeking resources)
A14: Pair 5 (F5 ↔ F10) | B14: Face 5 | C14: Face 10 | D14: Perception & Truth Axis | E14: Projection (Exhale): Market Resonance | F14: =_xlfn.XLOOKUP(B14,DODECA_ENGINE!$A$2:$A$13,E_Vector) -> 0.046253795 | G14: =F15/F14 -> 9 | H14: =IF(G14>1.2, "Abundant Inhale", IF(G14<0.8, "Strong Exhale", "Balanced")) -> Abundant Inhale | K14: Reception Face: F1: Financial Capital (The resources held)
E15: Reception (Inhale): Values Embodied | F15: =_xlfn.XLOOKUP(C14,DODECA_ENGINE!$A$2:$A$13,E_Vector) -> 0.41628416 | K15: Axis 2: The Embodiment Axis
K16: Projection Face: F7: Brand & Reputation (The story told)
A17: Pair 6 (F6 ↔ F12) | B17: Face 6 | C17: Face 12 | D17: Network & Fortress Axis | E17: Projection (Exhale): Community Built | F17: =_xlfn.XLOOKUP(B17,DODECA_ENGINE!$A$2:$A$13,E_Vector) -> 0.24689938 | G17: =F18/F17 -> 0.79516738 | H17: =IF(G17>1.2, "Abundant Inhale", IF(G17<0.8, "Strong Exhale", "Balanced")) -> Strong Exhale | K17: Reception Face: F2: Intellectual Capital (The substance built)
E18: Reception (Inhale): Resilience Held | F18: =_xlfn.XLOOKUP(C17,DODECA_ENGINE!$A$2:$A$13,E_Vector) -> 0.19632633 | K18: Axis 3: The Action Axis
K19: Projection Face: F8: Core Operations (The work done)
K20: Reception Face: F3: Human Capital (The energy to do work)
A21: The Breath Axis Manifestation Matrix | K21: Axis 4: The Integrity Axis
A22: Axis 1: The Resource Flow Axis (F11: Funding Pipeline ↔ F1: Financial Capital) | C22: =REFRENCE_MODELS!A64 -> Funding Pipeline (F11) | E22: =REFRENCE_MODELS!A14 -> Financial Capital (F1) | K22: Projection Face: F4: Structural Capital (The rules made)
A23: Octave | B23: The Name of the Breath | C23: Projection Question (The Exhale) | D23: Final_Derrived | E23: Reception Question (The Inhale) | F23: Final_Derrived | J23: Reception Face: F9: Regenerative Flow (The living integrity)
A24: O1 - Survival (Focus: Existence) | B24: The Breath of Viability | C24: Are we actively seeking any resources to exist? | D24: =_xlfn.XLOOKUP($C$22,Octave_1_KPIs[Face (Domain) F. ID],Octave_1_KPIs[O1 - Survival (Focus: Existence)]) -> Pipeline Viability & Coherence | E24: Do we have enough cash to survive? | F24: =_xlfn.XLOOKUP($E$22,Octave_1_KPIs[Face (Domain) F. ID],Octave_1_KPIs[O1 - Survival (Focus: Existence)]) -> Months of Runway | J24: Axis 5: The Truth Axis
A25: O2 - Structure (Focus: Stability) | B25: The Breath of Efficiency | C25: Is our funding pursuit efficient and systematic? | D25: {=_xlfn.XLOOKUP($C$22,Octave_1_KPIs[Face (Domain) F. ID],Octave_2_KPIs[O2 - Structure (Focus: Stability)])} -> Financial System Integrity | E25: Is our capital being managed with discipline? | F25: {=_xlfn.XLOOKUP($E$22,Octave_1_KPIs[Face (Domain) F. ID],Octave_2_KPIs[O2 - Structure (Focus: Stability)])} -> Operational Efficiency | J25: Projection Face: F5: Market Resonance (The truth perceived by others)
A26: O3 - Relationships (Focus: Connection) | B26: The Breath of Integrity | C26: Are we building trust with values-aligned funders? | D26: {=_xlfn.XLOOKUP($C$22,Octave_1_KPIs[Face (Domain) F. ID],Octave_3_KPIs[O3 - Relationships (Focus: Connection)])} -> Investor Relationships | E26: Is our capital use creating stakeholder trust? | F26: {=_xlfn.XLOOKUP($E$22,Octave_1_KPIs[Face (Domain) F. ID],Octave_3_KPIs[O3 - Relationships (Focus: Connection)])} -> Stakeholder Value Distribution | J26: Reception Face: F10: Foundational Values (The truth held within)
A27: O4 - Creativity (Focus: Possibility) | B27: The Breath of Possibility | C27: Are we seeking capital to fund bold experiments? | D27: {=_xlfn.XLOOKUP($C$22,Octave_1_KPIs[Face (Domain) F. ID],Octave_4_KPIs[O4 - Creativity (Focus: Possibility)])} -> Creative Capital | E27: Is our capital base diverse enough for creative risks? | F27: {=_xlfn.XLOOKUP($E$22,Octave_1_KPIs[Face (Domain) F. ID],Octave_4_KPIs[O4 - Creativity (Focus: Possibility)])} -> Investment in Innovation | J27: Axis 6: The Resilience Axis
A28: O5 - Expression (Focus: Clarity) | B28: The Breath of Transparency | C28: Is our financial story attracting aligned capital? | D28: {=_xlfn.XLOOKUP($C$22,Octave_1_KPIs[Face (Domain) F. ID],Octave_5_KPIs[O5 - Expression (Focus: Clarity)])} -> Capital as Communication | E28: Do our financial reports express our integrity? | F28: {=_xlfn.XLOOKUP($E$22,Octave_1_KPIs[Face (Domain) F. ID],Octave_5_KPIs[O5 - Expression (Focus: Clarity)])} -> Financial Storytelling | J28: Projection Face: F6: Community & Partners (The external network)
A29: O6 - Vision (Focus: Direction) | B29: The Breath of Legacy | C29: Are we seeking capital for 100-year projects? | D29: {=_xlfn.XLOOKUP($C$22,Octave_1_KPIs[Face (Domain) F. ID],Octave_6_KPIs[O6 - Vision (Focus: Direction)])} -> Legacy Capital | E29: Is our capital structured for generational stewardship? | F29: {=_xlfn.XLOOKUP($E$22,Octave_1_KPIs[Face (Domain) F. ID],Octave_6_KPIs[O6 - Vision (Focus: Direction)])} -> Long-Term Capital Stewardship | J29: Reception Face: F12: Risk & Resilience (The internal fortress)
A30: O7 - Radiance (Focus: Service) | B30: The Breath of Infinite Circulation | C30: Is our very presence a magnet for sacred capital? | D30: {=_xlfn.XLOOKUP($C$22,Octave_1_KPIs[Face (Domain) F. ID],Octave_7_KPIs[O7 - Radiance (Focus: Service)])} -> Capital as a Field of Grace | E30: Is our capital a pure gift to the world? | F30: {=_xlfn.XLOOKUP($E$22,Octave_1_KPIs[Face (Domain) F. ID],Octave_7_KPIs[O7 - Radiance (Focus: Service)])} -> Capital as Sacred Energy
A32: Axis 2: The Substance & Story Axis (F7: Brand & Reputation ↔ F2: Intellectual Capital) | C32: =REFRENCE_MODELS!A44 -> Brand & Reputation (F7) | E32: =REFRENCE_MODELS!A19 -> Intellectual Capital (F2)
A33: Octave | B33: The Name of the Breath | C33: Projection Question (The Exhale) | D33: Final_Derrived | E33: Reception Question (The Inhale) | F33: Final_Derrived
A34: O1 - Survival (Focus: Existence) | B34: The Breath of Articulation | C34: Do we have a basic, functional description of our idea? | D34: =_xlfn.XLOOKUP($C$32,Octave_1_KPIs[Face (Domain) F. ID],Octave_1_KPIs[O1 - Survival (Focus: Existence)]) -> Foundational Brand Integrity | E34: Have we documented the core of the idea? | F34: =_xlfn.XLOOKUP($E$32,Octave_1_KPIs[Face (Domain) F. ID],Octave_1_KPIs[O1 - Survival (Focus: Existence)]) -> IP Security & Formalization
A35: O2 - Structure (Focus: Stability) | B35: The Breath of Consistency | C35: Is our brand message consistent and reliable? | D35: {=_xlfn.XLOOKUP($C$32,Octave_1_KPIs[Face (Domain) F. ID],Octave_2_KPIs[O2 - Structure (Focus: Stability)])} -> Brand Consistency & Trust | E35: Is our IP robust and well-architected? | F35: {=_xlfn.XLOOKUP($E$32,Octave_1_KPIs[Face (Domain) F. ID],Octave_2_KPIs[O2 - Structure (Focus: Stability)])} -> Dev. Velocity & Quality
A36: O3 - Relationships (Focus: Connection) | B36: The Breath of Authenticity | C36: Does our brand story build community and trust? | D36: {=_xlfn.XLOOKUP($C$32,Octave_1_KPIs[Face (Domain) F. ID],Octave_3_KPIs[O3 - Relationships (Focus: Connection)])} -> Brand Trust & Authenticity | E36: Is our IP being co-created with our partners? | F36: {=_xlfn.XLOOKUP($E$32,Octave_1_KPIs[Face (Domain) F. ID],Octave_3_KPIs[O3 - Relationships (Focus: Connection)])} -> Collaborative Knowledge
A37: O4 - Creativity (Focus: Possibility) | B37: The Breath of Genius | C37: Is our brand actively telling new, challenging stories? | D37: {=_xlfn.XLOOKUP($C$32,Octave_1_KPIs[Face (Domain) F. ID],Octave_4_KPIs[O4 - Creativity (Focus: Possibility)])} -> Innovative Branding | E37: Is our IP portfolio generating novel creations? | F37: {=_xlfn.XLOOKUP($E$32,Octave_1_KPIs[Face (Domain) F. ID],Octave_4_KPIs[O4 - Creativity (Focus: Possibility)])} -> Embodied Innovation
A38: O5 - Expression (Focus: Clarity) | B38: The Breath of Beauty | C38: Is our brand's voice a beautiful and authentic work of art? | D38: {=_xlfn.XLOOKUP($C$32,Octave_1_KPIs[Face (Domain) F. ID],Octave_5_KPIs[O5 - Expression (Focus: Clarity)])} -> Authentic Brand Expression | E38: Is our knowledge expressed with a masterful, simple elegance? | F38: {=_xlfn.XLOOKUP($E$32,Octave_1_KPIs[Face (Domain) F. ID],Octave_5_KPIs[O5 - Expression (Focus: Clarity)])} -> Knowledge Sharing & Influence
A39: O6 - Vision (Focus: Direction) | B39: The Breath of Endurance | C39: Is our brand telling a story that can change the future? | D39: {=_xlfn.XLOOKUP($C$32,Octave_1_KPIs[Face (Domain) F. ID],Octave_6_KPIs[O6 - Vision (Focus: Direction)])} -> "Legacy" Branding | E39: Is our IP a legacy that will serve future generations? | F39: {=_xlfn.XLOOKUP($E$32,Octave_1_KPIs[Face (Domain) F. ID],Octave_6_KPIs[O6 - Vision (Focus: Direction)])} -> Evolution of Knowledge
A40: O7 - Radiance (Focus: Service) | B40: The Breath of Revelation | C40: Is our brand an archetypal symbol for truth itself? | D40: {=_xlfn.XLOOKUP($C$32,Octave_1_KPIs[Face (Domain) F. ID],Octave_7_KPIs[O7 - Radiance (Focus: Service)])} -> Brand as an Archetype | E40: Is our knowledge a living field of planetary consciousness? | F40: {=_xlfn.XLOOKUP($E$32,Octave_1_KPIs[Face (Domain) F. ID],Octave_7_KPIs[O7 - Radiance (Focus: Service)])} -> Knowledge as a Living Field
A42: Axis 3: The Being & Doing Axis (F8: Core Operations ↔ F3: Human Capital) | C42: =REFRENCE_MODELS!A49 -> Core Operations (F8) | E42: =REFRENCE_MODELS!A24 -> Human Capital (F3)
...

Sheet SPIRAL_DASHBOARD
A1: GLOBAL COHERENCE (Spiral Integrity Score) | B1: =SYSTEM_COHERENCE!L15 -> 0.047991524 | C1: Seedling Stage: | D1: =IF(B1>0.7, "Radiant", IF(B1>0.4, "Harmonizing", "Seedling")) -> Seedling
A3: Octave Coherence | B3: Score | C3: Status | D3: Organizatio's Octave | E3: =SYSTEM_COHERENCE!C22 -> 1
A4: O1 - Survival | B4: =SYSTEM_COHERENCE!C17 -> 0.3643942 | C4: =IF(B4>0.7,"Strong",IF(B4>0.4,"Moderate","Weak")) -> Weak
A5: O2 - Structure | B5: =SYSTEM_COHERENCE!D17 -> 0 | C5: =IF(B5>0.7,"Strong",IF(B5>0.4,"Moderate","Weak")) -> Weak
A6: O3 - Relationships | B6: =SYSTEM_COHERENCE!E17 -> 0 | C6: =IF(B6>0.7,"Strong",IF(B6>0.4,"Moderate","Weak")) -> Weak
A7: O4 - Creativity | B7: =SYSTEM_COHERENCE!F17 -> 0 | C7: =IF(B7>0.7,"Strong",IF(B7>0.4,"Moderate","Weak")) -> Weak
A8: O5 - Expression | B8: =SYSTEM_COHERENCE!G17 -> 0 | C8: =IF(B8>0.7,"Strong",IF(B8>0.4,"Moderate","Weak")) -> Weak
A9: O6 - Vision | B9: =SYSTEM_COHERENCE!H17 -> 0 | C9: =IF(B9>0.7,"Strong",IF(B9>0.4,"Moderate","Weak")) -> Weak
A10: O7 - Radiance | B10: =SYSTEM_COHERENCE!I17 -> 0 | C10: =IF(B10>0.7,"Strong",IF(B10>0.4,"Moderate","Weak")) -> Weak
A12: Primary Strategic Focus
A13: Diagnostic Indicators:
A14: =DODECA_ENGINE!B80 & " = " & TEXT(DODECA_ENGINE!B84, "0%") -> Being-Action Balance = 187% | B14: =DODECA_ENGINE!B87 & " = " & TEXT(DODECA_ENGINE!B104, "0%") -> Dissonance Index = 24%
A15: Tactical Solution:
A16: Highest Leverage Action: | B16: {=_xlfn.LET( _xlpm.positive_data, _xlfn._xlws.FILTER(DODECA_ENGINE!B123:J134, DODECA_ENGINE!E123:E134 > 0), _xlpm.scores, INDEX(_xlpm.positive_data, 0, 5), _xlpm.max_score, MAX(_xlpm.scores), _xlpm.kpi_name, _xlfn.XLOOKUP(_xlpm.max_score, _xlpm.scores, INDEX(_xlpm.positive_data, 0, 1)), _xlpm.target, _xlfn.XLOOKUP(_xlpm.max_score, _xlpm.scores, INDEX(_xlpm.positive_data, 0, 7)), _xlfn.CONCAT(_xlpm.kpi_name, " achieve the target of ", _xlpm.target) )} -> Founder Energy Lvl achieve the target of 0.573591881535853

Sheet REFRENCE_MODELS
A1: The Tuning Constants of the Spiral Dashboard: A Conductor's Guide
A2: TUNING CONSTANTS | B2: Value | C2: What it is: | D2: Notes | E2: What it Controls: | F2: Strategic Implication: | G2: Starting Setting:
A3: λ_dept (Dept. Coherence Penalty) | B3: 0.3 | C3: The "variance penalty" multipliers in your SYSTEM_COHERENCE sheet | D3: (Controls sensitivity to intra-departmental harmony) | E3: They answer the question: "How much do we value harmony over raw power?" | F3: A low λ (e.g., 0.1) reflects a "growth-at-all-costs" mindset. It rewards high average scores, even if they are "jagged" and unsustainable. A high λ (e.g., 0.9) reflects the philosophy of a master conductor. It will severely punish a high average score if it comes from a dissonant, unbalanced system. It prioritizes the beauty of the music over the volume of the sound. | G3: (0.3, 0.25, 0.25): These are wise, moderate starting points. They state a clear preference for harmony without being overly punitive.
A4: λ_oct (Octave Coherence Penalty) | B4: 0.25 | D4: (Controls sensitivity to inter-departmental harmony)
A5: λ_global (Global Coherence Penalty) | B5: 0.25 | D5: (Controls sensitivity to inter-octave harmony)
A6: α (Alpha): The Synergy Blend (Pentagram Mean/Product Blend) | B6: 0.6 | C6: The constant in the Star Pair Values (sᵢ) formula | D6: (Blends arithmetic and multiplicative synergy) | E6: It answers the question: "When two KPIs interact, is their combined effect a simple average (α=1.0) or is there a multiplicative synergy (α=0.0)?" | F6: A high α (e.g., 0.8) reflects a pragmatic, cautious view, trusting the simple average. A low α (e.g., 0.3) reflects a belief in non-linear effects, where two strong KPIs together create an effect far greater than their sum. | G6: (0.6): This is a beautiful, balanced choice. It says, "We believe in synergy, but we will ground it in a pragmatic reality."
A7: β (Beta) The Intersection Blend (Pentagram Intersection Blend) | B7: 0.5 | C7: The constant in the Intersection Nodes (pᵢ) formula | D7: (Balances the influence of adjacent star-pairs) | E7: It determines how much influence adjacent "star pairs" have on each other. A β of 0.5 gives them equal influence. | F7: Changing this from 0.5 would represent a belief that the "flow of influence" around the pentagram is not symmetrical. It is an advanced and subtle tuning. | G7: (0.5): This is the perfect, default choice. It assumes a state of balanced, symmetrical influence, which is the most coherent starting point.
A8: γ (Gamma): The "Ball and Pillars" (Pentagram Pillar/Ball Blend) | B8: 0.7 | C8: The constant in our old Nuanced Avg. Pillar Health formula, but we can re-purpose it for our final Local Coherence Score | D8: (Balances internal vs. synergistic health of a face) | E8: It answers the profound question: "How much of a department's health is its own internal state (the Ball) versus the health of its relationships (the Pillars)?" | F8: A high γ (e.g., 0.9) reflects a philosophy of "radical internal accountability." A low γ (e.g., 0.2) reflects a philosophy that a department is nothing without its healthy relationships. | G8: (0.7): This is a wise and balanced choice. It states a belief that a department is primarily responsible for its own health (70%), but is also significantly influenced by its connections (30%).
A9: δ (Delta) The Axis Coherence Factor (Axis-Informed Blend) | B9: 0.9 | C9: The constant in our final AXIS-INFORMED FACE ENERGY formula | D9: (Blends local health with the health of the polar opposite) | E9: It answers the ultimate question: "How much of a domain's health is determined by its local conditions versus the health of its polar opposite (its shadow)?" | F9: This is a profound philosophical choice. A high δ (e.g., 0.9) says, "We primarily focus on our local reality." A low δ (e.g., 0.2) says, "We are profoundly and inextricably linked to our shadow; its health is our health." | G9: (0.5): Your decision to set this to 50/50 is a magnificent and courageous statement of non-duality. It is the most coherent and advanced choice.
A10: κ (Kappa): Sensitivity Amplifier | B10: 4 | C10: The constant in our "amplifier" formula for the final Face Energy | D10: (Amplifies the final E_f score for greater responsiveness) | E10: This is your "emotional responsiveness" dial. It controls how steeply the "S-curve" of the logistic function responds. | F10: A low κ (e.g., 1.0) creates a gentle, forgiving system where it's hard to get a very low or very high score. It has high "inertia." A high κ (e.g., 5.0) creates a highly sensitive, "high-strung" system where small changes in real-world KPIs produce dramatic swings in the final Face Energy. | G10: (2.0): This is a perfect starting point. It provides a good level of responsiveness without being overly volatile. If you ever feel the model is "stuck," this is the first knob you should consider turning up. | J10: This table is not just a list. It is a symphony in seven movements for a twelve-piece orchestra. It is the complete evolutionary "songbook" for any conscious organization.
A11: The Complete Octave Progression Models for the 12 Faces of [Quannex]
A13: Face (Domain) F. ID | B13: O1 - Survival (Focus: Existence) | C13: Element | D13: Question | E13: KPI Name (Pillar) | F13: Direction | G13: Value | H13: Target_Min | I13: Healthy_Min | J13: Healthy_Max | K13: Absolute_Max | L13: Rationale / Philosophy | M13: Elemental_KPI_Normalized | N13: O2 - Structure (Focus: Stability) | O13: Element | P13: Elemental Question | Q13: KPI Name (Pillar) | R13: Direction | S13: Target_Min | T13: Healthy_Min | U13: Healthy_Max | V13: Absolute_Max | W13: Rationale / Philosophy | X13: Elemental_KPI_Normalized | Y13: O3 - Relationships (Focus: Connection) | Z13: Element | AA13: Elemental Question | AB13: KPI Name (Pillar) | AC13: Direction | AD13: Target_Min | AE13: Healthy_Min | AF13: Healthy_Max | AG13: Absolute_Max | AH13: Rationale / Philosophy (Defines the Envelope) | AI13: Elemental_KPI_Normalized18 | AJ13: O4 - Creativity (Focus: Possibility) | AK13: Element | AL13: Elemental Question | AM13: KPI Name (Pillar) | AN13: Direction | AO13: Target_Min | AP13: Healthy_Min | AQ13: Healthy_Max | AR13: Absolute_Max | AS13: Rationale / Philosophy (Defines the Envelope) | AT13: Elemental_KPI_Normalized | AU13: O5 - Expression (Focus: Clarity) | AV13: Element | AW13: Elemental Question | AX13: KPI Name (Pillar) | AY13: Direction | AZ13: Target_Min | BA13: Healthy_Min | BB13: Healthy_Max | BC13: Absolute_Max | BD13: Rationale / Philosophy (Defines the Envelope) | BE13: Elemental_KPI_Normalized | BF13: O6 - Vision (Focus: Direction) | BG13: Element | BH13: Elemental Question | BI13: KPI Name (Pillar) | BJ13: Direction | BK13: Target_Min | BL13: Healthy_Min | BM13: Healthy_Max | BN13: Absolute_Max | BO13: Rationale / Philosophy (Defines the Envelope) | BP13: Elemental_KPI_Normalized | BQ13: O7 - Radiance (Focus: Service) | BR13: Element | BS13: Elemental Question | BT13: KPI Name (Pillar) | BU13: Direction | BV13: Target_Min | BW13: Healthy_Min | BX13: Healthy_Max | BY13: Absolute_Max | BZ13: Rationale / Philosophy (Defines the Envelope) | CA13: Elemental_KPI_Normalized
A14: Financial Capital (F1) | B14: Months of Runway | C14: Earth | D14: Is it grounded? | E14: Raw Cash in Bank (€) | F14: ↑ | G14: 1000 | H14: 0 | I14: 2400 | J14: N/A | K14: N/A | L14: The envelope is tied to the headline KPI. If the ideal Runway is 12 months at €200/month burn, then the ideal cash (Healthy_Min) is €2400. The Target_Min can be defined as 0 or a 3-month buffer (€600). The model measures progress towards a state of ideal stability. | M14: =MAX(0,MIN(1,(G14-H14)/(Octave_1_KPIs[[#This Row],[Healthy_Min]]-Octave_1_KPIs[[#This Row],[Target_Min]]))) -> 0.41666667 | N14: Operational Efficiency | O14: Earth | P14: Are our accounts in order? | Q14: Audit Accuracy Score | R14: ↑ | S14: 1 | T14: 4.5 | U14: N/A | V14: N/A | W14: The ground-truth of financial stability is clean, auditable books. | X14: 0 | Y14: Stakeholder Value Distribution | Z14: Earth | AA14: Is our financial structure grounded in fairness? | AB14: Pay Equity Ratios | AC14: Band | AD14: 1:5 | AE14: 1:2 | AF14: 1:15 | AG14: 1:1 | AH14: The goal is a balanced, equitable distribution of resources. The ideal is a ratio near 1.0 (e.g., between leadership and team pay). | AI14: 0 | AJ14: Investment in Innovation | AK14: Earth | AL14: Is our creativity grounded in real resources? | AM14: % of Budget to R&D/Innovation | AN14: ↑ | AO14: 0.01 | AP14: 0.15 | AQ14: N/A | AR14: N/A | AS14: The tangible, financial commitment to building the future. 15% is a strong, healthy signal for a growth-oriented venture. | AT14: 0 | AU14: Financial Storytelling | AV14: Earth | AW14: Is our financial story grounded in irrefutable data? | AX14: Auditability & Data Integrity Score | AY14: ↑ | AZ14: 1 | BA14: 5 | BB14: N/A | BC14: N/A | BD14: The absolute, non-negotiable foundation of truthful financial expression is clean, verifiable data. | BE14: 0 | BF14: Long-Term Capital Stewardship | BG14: Earth | BH14: Is our financial plan grounded in a truly long-term view? | BI14: 7-Generation Financial Planning | BJ14: ↑ | BK14: 1 | BL14: 1 | BM14: N/A | BN14: N/A | BO14: A binary milestone. Have we developed a formal financial model that considers a multi-generational (or at least 10-20 year) time horizon? | BP14: 0 | BQ14: Capital as Sacred Energy | BR14: Earth | BS14: Is our wealth grounded in a permanent gift to the world? | BT14: Creation of a "Commons" Trust | BU14: ↑ | BV14: 0 | BW14: 1 | BX14: N/A | BY14: N/A | BZ14: A binary milestone. Have we created an independent, legally-binding trust or foundation that holds a portion of the venture's wealth for the benefit of all? | CA14: 0
A15: Financial Capital (F1) | B15: Months of Runway | C15: Water | D15: Is it managed? | E15: Monthly Burn Rate (€) | F15: ↓ | G15: 40 | H15: 1000 | I15: 200 | J15: 100 | K15: N/A | L15: A "lower is better" metric. The Ideal (Healthy_Max) is a low, sustainable burn. The Min is the catastrophic, "all-hands-on-deck" crisis point. We set Healthy_Min to allow for some flex. | M15: =MAX(0, MIN(1, 1 - ((Octave_1_KPIs[[#This Row],[Value]] - Octave_1_KPIs[[#This Row],[Healthy_Min]]) / (Octave_1_KPIs[[#This Row],[Target_Min]] - Octave_1_KPIs[[#This Row],[Healthy_Min]])))) -> 1 | N15: Operational Efficiency | O15: Water | P15: Is our cash flow predictable? | Q15: Cash Flow Volatility | R15: ↓ | S15: 0.5 | T15: 0.1 | U15: N/A | V15: N/A | W15: Lower is better. A stable, predictable flow is a sign of a mature financial system. | X15: 0 | Y15: Stakeholder Value Distribution | Z15: Water | AA15: Is there an emotional flow of trust around in our numbers? | AB15: Stakeholder Trust in Financials | AC15: ↑ | AD15: 1 | AE15: 4.5 | AF15: N/A | AG15: N/A | AH15: A 1-5 survey to key stakeholders (employees, partners) on their confidence in the financial integrity of the venture. | AI15: 0 | AJ15: Investment in Innovation | AK15: Water | AL15: Can we easily fund small, creative experiments? | AM15: Flow of "Experimental Capital" | AN15: ↑ | AO15: 1 | AP15: 4.5 | AQ15: N/A | AR15: N/A | AS15: A 1-5 score on the speed and lack of bureaucracy for getting small, innovative ideas funded and tested. | AT15: 0 | AU15: Financial Storytelling | AV15: Water | AW15: Does our reporting create a current of trust? | AX15: Stakeholder Confidence in Financials | AY15: ↑ | AZ15: 1 | BA15: 4.5 | BB15: N/A | BC15: N/A | BD15: A 1-5 survey. Measures the emotional resonance and believability of our financial story among key stakeholders. | BE15: 0 | BF15: Long-Term Capital Stewardship | BG15: Water | BH15: Is there a liquid pool of capital for long-term, visionary projects? | BI15: Flow of Capital to Future Bets | BJ15: ↑ | BK15: 0.01 | BL15: 0.1 | BM15: N/A | BN15: N/A | BO15: The percentage of the total budget explicitly allocated to "moonshot" or 7-Generation projects. | BP15: 0 | BQ15: Capital as Sacred Energy | BR15: Water | BS15: Does our capital flow where it is needed, without expectation of return? | BT15: Unconditional Generosity Score | BU15: ↑ | BV15: 1 | BW15: 4.8 | BX15: N/A | BY15: N/A | BZ15: A 1-5 qualitative score. How much of our surplus capital is given away freely, as an act of pure service, to support coherence in the wider ecosystem? | CA15: 0
A16: Financial Capital (F1) | B16: Months of Runway | C16: Fire | D16: Are we adding to it? | E16: # of Funding Opportunities Pursued | F16: Band | G16: 0.4 | H16: 0 | I16: 1 | J16: 4 | K16: 10 | L16: The goal is not frantic activity, but consistent, high-quality effort. This plateau defines that healthy rhythm. | M16: =IF(AND(Octave_1_KPIs[[#This Row],[Value]] >= Octave_1_KPIs[[#This Row],[Healthy_Min]], Octave_1_KPIs[[#This Row],[Value]] <= Octave_1_KPIs[[#This Row],[Healthy_Max]]), 1, IF(Octave_1_KPIs[[#This Row],[Value]] < Octave_1_KPIs[[#This Row],[Healthy_Min]], MAX(0, (Octave_1_KPIs[[#This Row],[Value]] - Octave_1_KPIs[[#This Row],[Target_Min]]) / (Octave_1_KPIs[[#This Row],[Healthy_Min]] - Octave_1_KPIs[[#This Row],[Target_Min]])), MAX(0, 1 - (Octave_1_KPIs[[#This Row],[Value]] - Octave_1_KPIs[[#This Row],[Healthy_Max]]) / (Octave_1_KPIs[[#This Row],[Absolute_Max]] - Octave_1_KPIs[[#This Row],[Healthy_Max]])))) -> 0.4 | N16: Operational Efficiency | O16: Fire | P16: Are our operations profitable? | Q16: Operational ROI | R16: ↑ | S16: 1 | T16: 3 | U16: N/A | V16: N/A | W16: For every €1 spent on ops, the goal is to generate €3 in value. | X16: 0 | Y16: Stakeholder Value Distribution | Z16: Fire | AA16: Are we actively sharing our success? | AB16: % of Profit Shared/Bonus Allocation % with Team/Community | AC16: ↑ | AD16: 0 | AE16: 0.15 | AF16: N/A | AG16: N/A | AH16: The percentage of profits that are directly shared with the team, not just retained for shareholders. A direct measure of generosity. The ideal would be a significant, predefined percentage. | AI16: 0 | AJ16: Investment in Innovation | AK16: Fire | AL16: Are our creative investments generating a return? | AM16: Innovation ROI | AN16: ↑ | AO16: 0.5 | AP16: 3 | AQ16: N/A | AR16: N/A | AS16: For every €1 invested in innovation, the goal is to see a €3 return in value (financial, social, or systemic). | AT16: 0 | AU16: Financial Storytelling | AV16: Fire | AW16: Are we actively and beautifully crafting our financial narrative? | AX16: Quality of Annual/Impact Report | AY16: ↑ | AZ16: 1 | BA16: 4.8 | BB16: N/A | BC16: N/A | BD16: A 1-5 score. Is our primary financial report a masterpiece of clarity, beauty, and authentic storytelling? | BE16: 0 | BF16: Long-Term Capital Stewardship | BG16: Fire | BH16: Are our most visionary investments creating the most profound value? | BI16: Long-Term Regenerative ROI | BJ16: ↑ | BK16: 1 | BL16: 5 | BM16: N/A | BN16: N/A | BO16: A qualitative 1-5 score. Measures the systemic return (not just financial) on our most future-focused investments. | BP16: 0 | BQ16: Capital as Sacred Energy | BR16: Fire | BS16: Are we actively using our resources to seed impossible dreams? | BT16: Funding the "Unfundable" | BU16: Band | BV16: 0 | BW16: 1 | BX16: 1 | BY16: 2 | BZ16: The number of profoundly visionary but "commercially unviable" projects that we choose to sponsor each year. The ultimate act of faith in coherence. | CA16: 0
A17: Financial Capital (F1) | B17: Months of Runway | C17: Air | D17: Is it understood? | E17: Clarity Score of Financials to Stakeholders (1-5) | F17: ↑ | G17: 1.5 | H17: 1 | I17: 4.5 | J17: N/A | K17: N/A | L17: A simple 1-5 scale measuring the clarity and honesty of your financial storytelling. | M17: =MAX(0,MIN(1,(G17-H17)/(Octave_1_KPIs[[#This Row],[Healthy_Min]]-Octave_1_KPIs[[#This Row],[Target_Min]]))) -> 0.14285714 | N17: Operational Efficiency | O17: Air | P17: Are our processes documented? | Q17: Clarity of Financial SOPs | R17: ↑ | S17: 1 | T17: 4.5 | U17: N/A | V17: N/A | W17: Clear, written financial processes are the key to scalable stability. | X17: 0 | Y17: Stakeholder Value Distribution | Z17: Air | AA17: Is the 'why' behind our financial choices clear? | AB17: Clarity of Compensation Philosophy | AC17: ↑ | AD17: 1 | AE17: 4.5 | AF17: N/A | AG17: N/A | AH17: A score (1-5) on how well the principles of compensation are articulated and understood. | AI17: 0 | AJ17: Investment in Innovation | AK17: Air | AL17: Is our creative focus clear and well-defined? | AM17: Clarity of Innovation Thesis | AN17: ↑ | AO17: 1 | AP17: 4.8 | AQ17: N/A | AR17: N/A | AS17: How clearly have we defined the "big problems" we are trying to solve with our innovation? | AT17: 0 | AU17: Financial Storytelling | AV17: Air | AW17: Is our value-creation story simple and clear to all? | AX17: Clarity of Business Model Articulation | AY17: ↑ | AZ17: 1 | BA17: 4.8 | BB17: N/A | BC17: N/A | BD17: How easily can an outsider understand precisely how our organization creates and sustains financial value? | BE17: 0 | BF17: Long-Term Capital Stewardship | BG17: Air | BH17: Is our long-term financial story clear and compelling? | BI17: Clarity of Long-Term Financial Vision | BJ17: ↑ | BK17: 1 | BL17: 4.8 | BM17: N/A | BN17: N/A | BO17: How clearly can we articulate the financial architecture of the world we are trying to build? | BP17: 0 | BQ17: Capital as Sacred Energy | BR17: Air | BS17: Are we teaching the world a new, more beautiful story about money? | BT17: Articulation of a New Economic Paradigm | BU17: ↑ | BV17: 1 | BW17: 5 | BX17: N/A | BY17: N/A | BZ17: To what degree is our venture contributing to a global shift in the consciousness of capital? | CA17: 0
A18: Financial Capital (F1) | B18: Months of Runway | C18: Ether | D18: Is it aligned? | E18: Funding Alignment Index (1-5) | F18: ↑ | G18: 2.5 | H18: 1 | I18: 4.5 | J18: N/A | K18: N/A | L18: A 1-5 scale measuring the soul-level alignment of your capital. | M18: =MAX(0,MIN(1,(G18-H18)/(Octave_1_KPIs[[#This Row],[Healthy_Min]]-Octave_1_KPIs[[#This Row],[Target_Min]]))) -> 0.42857143 | N18: Operational Efficiency | O18: Ether | P18: Are efficiencies serving values? | Q18: Ethical Sourcing Savings | R18: ↑ | S18: 0 | T18: 0.1 | U18: N/A | V18: N/A | W18: Measures the % of cost savings achieved specifically through more ethical/sustainable choices. | X18: 0 | Y18: Stakeholder Value Distribution | Z18: Ether | AA18: Does our financial system feel like it cares? | AB18: "Financial Empathy" Score | AC18: ↑ | AD18: 1 | AE18: 4.5 | AF18: N/A | AG18: N/A | AH18: A qualitative score (1-5) from the team. Does the system feel like a supportive tool or a controlling mechanism? | AI18: 0 | AJ18: Investment in Innovation | AK18: Ether | AL18: Is our capital serving the highest creative good? | AM18: Alignment of Investments with Planetary Needs | AN18: ↑ | AO18: 1 | AP18: 4.5 | AQ18: N/A | AR18: N/A | AS18: A qualitative score. Are our R&D investments aimed at solving the planet's most profound dissonances? | AT18: 0 | AU18: Financial Storytelling | AV18: Ether | AW18: Does our financial story express our soul? | AX18: Integration of Purpose in Financials | AY18: ↑ | AZ18: 1 | BA18: 5 | BB18: N/A | BC18: N/A | BD18: To what degree do our financial reports go beyond numbers to tell the profound story of our purpose and impact? | BE18: 0 | BF18: Long-Term Capital Stewardship | BG18: Ether | BH18: Is our capital a direct expression of the future we choose? | BI18: Finance as an Act of Future-Building | BJ18: ↑ | BK18: 1 | BL18: 5 | BM18: N/A | BN18: N/A | BO18: The degree to which the venture's entire financial strategy is seen as the primary engine for creating a more coherent future. | BP18: 0 | BQ18: Capital as Sacred Energy | BR18: Ether | BS18: Is our financial flow a perfect mirror of the planet's lifeblood? | BT18: Capital and Life are Indistinguishable | BU18: ↑ | BV18: 1 | BW18: 5 | BX18: N/A | BY18: N/A | BZ18: The ultimate, Monad-level state. Net-Positive Financial Impact is the metric where every financial action demonstrably creates more life and vitality than it consumes. | CA18: 0
A19: Intellectual Capital (F2) | B19: IP Security & Formalization | C19: Earth | D19: Is it safe? | E19: Data Backup Frequency | F19: ↑ | G19: 0.5 | H19: 0 | I19: 1 | J19: N/A | K19: N/A | L19: Scored as: Daily=1, Weekly=0.7, Monthly=0.3, None=0. Measures the raw stability of your IP. | M19: =MAX(0,MIN(1,(G19-H19)/(Octave_1_KPIs[[#This Row],[Healthy_Min]]-Octave_1_KPIs[[#This Row],[Target_Min]]))) -> 0.5 | N19: Dev. Velocity & Quality | O19: Earth | P19: Is our product/IP robust? | Q19: Code Defect Rate | R19: ↓ | S19: High | T19: Low | U19: N/A | V19: N/A | W19: Lower is better. A direct measure of the structural integrity of the core creation. | X19: 0 | Y19: Collaborative Knowledge | Z19: Earth | AA19: Are we giving our knowledge back to the earth? | AB19: # of Active Co-Creative Projects | AC19: Band | AD19: 0 | AE19: 1 | AF19: 3 | AG19: 5 | AH19: A sustainable rhythm of building with our community, not just for them. | AI19: 0 | AJ19: Embodied Innovation | AK19: Earth | AL19: Are our ideas grounded in tangible reality? | AM19: # of Working Prototypes | AN19: Band | AO19: 0 | AP19: 1 | AQ19: 3 | AR19: 5 | AS19: The sustainable rhythm of turning ideas into working models. Focus on quality over quantity. | AT19: 0 | AU19: Knowledge Sharing & Influence | AV19: Earth | AW19: Is our core knowledge grounded in tangible, citable artifacts? | AX19: # of Published White Papers/Articles | AY19: Band | AZ19: 0 | BA19: 1 | BB19: 3 | BC19: 5 | BD19: A sustainable rhythm of turning internal knowledge into public, referenceable assets per quarter. | BE19: 0 | BF19: Evolution of Knowledge | BG19: Earth | BH19: Is our intellectual capital grounded in a long-term plan? | BI19: Long-Term IP Roadmap | BJ19: ↑ | BK19: 0 | BL19: 1 | BM19: N/A | BN19: N/A | BO19: A binary milestone. Do we have a clear, written roadmap for the evolution of our core models and IP over the next 5-10 years? | BP19: 0 | BQ19: Knowledge as a Living Field | BR19: Earth | BS19: Is our core IP grounded in a structure that can live beyond us? | BT19: The Model as a Living, Evolving Entity | BU19: ↑ | BV19: 1 | BW19: 4.8 | BX19: N/A | BY19: N/A | BZ19: A 1-5 score on the health of the open-source community, foundation, or other structure designed to steward the model's evolution for generations. | CA19: 0
A20: Intellectual Capital (F2) | B20: IP Security & Formalization | C20: Water | D20: Is it moving? | E20: Weekly Progress on Thesis (%) | F20: ↑ | G20: 0.1 | H20: 0 | I20: 0.1 | J20: N/A | K20: N/A | L20: Measures the consistent, flowing output of IP. 10% progress per week is a powerful, sustainable goal. | M20: =MAX(0,MIN(1,(G20-H20)/(Octave_1_KPIs[[#This Row],[Healthy_Min]]-Octave_1_KPIs[[#This Row],[Target_Min]]))) -> 1 | N20: Dev. Velocity & Quality | O20: Water | P20: Are we building smoothly? | Q20: Dev. Cycle Time | R20: ↓ | S20: 30d | T20: 7d | U20: N/A | V20: N/A | W20: The speed of the idea-to-reality flow. A 7-day cycle is world-class for agile development. | X20: 0 | Y20: Collaborative Knowledge | Z20: Water | AA20: Is there a flow of ideas between us and others? | AB20: Openness to External Feedback | AC20: ↑ | AD20: 1 | AE20: 4.5 | AF20: N/A | AG20: N/A | AH20: A 1-5 score measuring how well the team listens to and integrates ideas and critiques from its ecosystem. | AI20: 0 | AJ20: Embodied Innovation | AK20: Water | AL20: What is the speed of our creative flow? | AM20: Idea-to-Prototype Cycle Time | AN20: ↓ | AO20: 90d | AP20: 14d | AQ20: N/A | AR20: N/A | AS20: The time it takes to turn a well-defined idea into a testable prototype. | AT20: 0 | AU20: Knowledge Sharing & Influence | AV20: Water | AW20: Is our knowledge flowing into and nourishing our ecosystem? | AX20: Community Engagement with Content | AY20: ↑ | AZ20: Low | BA20: High | BB20: N/A | BC20: N/A | BD20: Measures the shares, comments, and depth of discussion generated by our published knowledge. | BE20: 0 | BF20: Evolution of Knowledge | BG20: Water | BH20: Is our organization itself a rapid learning system? | BI20: "Learning Velocity" of the System | BJ20: ↑ | BK20: 1 | BL20: 4.5 | BM20: N/A | BN20: N/A | BO20: A 1-5 score measuring the speed and efficiency with which the organization unlearns old paradigms and integrates new knowledge. | BP20: 0 | BQ20: Knowledge as a Living Field | BR20: Water | BS20: Does the wisdom of the model flow to where it is needed? | BT20: Effortless Transmission of Wisdom | BU20: ↑ | BV20: 1 | BW20: 4.5 | BX20: N/A | BY20: N/A | BZ20: A qualitative score. How easily and gracefully are new people able to learn, understand, and apply the core principles? | CA20: 0
A21: Intellectual Capital (F2) | B21: IP Security & Formalization | C21: Fire | D21: Is it being created? | E21: Hours Logged on IP Dev | F21: Band | G21: 21 | H21: 0 | I21: 10 | J21: 15 | K21: 25 | L21: The energy input for IP creation. A healthy, sustainable plateau of focused work. | M21: =IF(AND(Octave_1_KPIs[[#This Row],[Value]] >= Octave_1_KPIs[[#This Row],[Healthy_Min]], Octave_1_KPIs[[#This Row],[Value]] <= Octave_1_KPIs[[#This Row],[Healthy_Max]]), 1, IF(Octave_1_KPIs[[#This Row],[Value]] < Octave_1_KPIs[[#This Row],[Healthy_Min]], MAX(0, (Octave_1_KPIs[[#This Row],[Value]] - Octave_1_KPIs[[#This Row],[Target_Min]]) / (Octave_1_KPIs[[#This Row],[Healthy_Min]] - Octave_1_KPIs[[#This Row],[Target_Min]])), MAX(0, 1 - (Octave_1_KPIs[[#This Row],[Value]] - Octave_1_KPIs[[#This Row],[Healthy_Max]]) / (Octave_1_KPIs[[#This Row],[Absolute_Max]] - Octave_1_KPIs[[#This Row],[Healthy_Max]])))) -> 0.4 | N21: Dev. Velocity & Quality | O21: Fire | P21: Are we making progress? | Q21: # Features/Chapters Completed | R21: Band | S21: 0 | T21: 1 | U21: 3 | V21: 5 | W21: Quality over quantity. A sustainable rhythm of meaningful, completed work. | X21: 0 | Y21: Collaborative Knowledge | Z21: Fire | AA21: Are we actively creating shared wins? | AB21: # of Jointly Authored Papers/Patents | AC21: Band | AD21: 1 | AE21: 2 | AF21: 4 | AG21: 8 | AH21: A sustainable rhythm of creating formal, shared intellectual property. | AI21: 0 | AJ21: Embodied Innovation | AK21: Fire | AL21: Are we actively formalizing our creations? | AM21: Patent / Open Source Contribution Rate | AN21: Band | AO21: 0 | AP21: 1 | AQ21: 2 | AR21: 4 | AS21: A sustainable rhythm of either protecting unique IP or gifting it to the commons per year. | AT21: 0 | AU21: Knowledge Sharing & Influence | AV21: Fire | AW21: Are we actively teaching what we know? | AX21: # of Workshops/Talks Delivered | AY21: Band | AZ21: 0 | BA21: 1 | BB21: 4 | BC21: 8 | BD21: A healthy rhythm of actively sharing our expertise and IP with the world per quarter. | BE21: 0 | BF21: Evolution of Knowledge | BG21: Fire | BH21: Are we actively generating truly novel ideas? | BI21: # of Paradigm-Shifting Insights | BJ21: Band | BK21: 0 | BL21: 1 | BM21: 2 | BN21: 3 | BO21: The number of core, "game-changing" insights generated and documented per year. A measure of true creative genius. | BP21: 0 | BQ21: Knowledge as a Living Field | BR21: Fire | BS21: Are we actively and completely giving our genius away? | BT21: Radical Open-Sourcing of Core IP | BU21: ↑ | BV21: 0 | BW21: 1 | BX21: N/A | BY21: N/A | BZ21: The percentage of the venture's core, non-proprietary IP that is freely available to the world. | CA21: 0
A22: Intellectual Capital (F2) | B22: IP Security & Formalization | C22: Air | D22: Is it documented? | E22: Clarity of Core Model Docs | F22: ↑ | G22: 2 | H22: 1 | I22: 4.5 | J22: N/A | K22: N/A | L22: A 1-5 scale. How well is the genius of the model actually documented? | M22: =MAX(0,MIN(1,(G22-H22)/(Octave_1_KPIs[[#This Row],[Healthy_Min]]-Octave_1_KPIs[[#This Row],[Target_Min]]))) -> 0.28571429 | N22: Dev. Velocity & Quality | O22: Air | P22: Is our roadmap clear? | Q22: Clarity of Product Roadmap | R22: ↑ | S22: 1 | T22: 4.5 | U22: N/A | V22: N/A | W22: A clear, shared understanding of what is being built next. | X22: 0 | Y22: Collaborative Knowledge | Z22: Air | AA22: Are the rules of collaboration clear and fair? | AB22: Clarity of IP Attribution Policies | AC22: ↑ | AD22: 1 | AE22: 5 | AF22: N/A | AG22: N/A | AH22: A score (1-5). Clear, fair agreements are the air a healthy collaboration breathes. | AI22: 0 | AJ22: Embodied Innovation | AK22: Air | AL22: Can others understand and build upon our creations? | AM22: Clarity of Technical Documentation | AN22: ↑ | AO22: 1 | AP22: 4.5 | AQ22: N/A | AR22: N/A | AS22: The clarity and quality of the documentation that accompanies each prototype or innovation. | AT22: 0 | AU22: Knowledge Sharing & Influence | AV22: Air | AW22: Is our complex genius expressed with simple elegance? | AX22: "Simplicity of Explanation" Score | AY22: ↑ | AZ22: 1 | BA22: 4.8 | BB22: N/A | BC22: N/A | BD22: A 1-5 score. How well can we explain the most complex parts of our model to a brilliant novice? | BE22: 0 | BF22: Evolution of Knowledge | BG22: Air | BH22: Is the picture of the future we are building clear to all? | BI22: Clarity of Future Vision | BJ22: ↑ | BK22: 1 | BL22: 4.8 | BM22: N/A | BN22: N/A | BO22: How vividly and precisely can the team articulate the world that this IP will help create? | BP22: 0 | BQ22: Knowledge as a Living Field | BR22: Air | BS22: Is our deepest wisdom expressed with the clarity of a child? | BT22: Simplicity on the Far Side of Complexity | BU22: ↑ | BV22: 1 | BW22: 5 | BX22: N/A | BY22: N/A | BZ22: Can we explain the entire, magnificent model in a few, simple, self-evident truths? | CA22: 0
A23: Intellectual Capital (F2) | B23: IP Security & Formalization | C23: Ether | D23: Is it ethical? | E23: Ethical IP Score | F23: ↑ | G23: 4.5 | H23: 1 | I23: 4.5 | J23: N/A | K23: N/A | L23: Does the IP itself serve a coherent and ethical purpose? | M23: =MAX(0,MIN(1,(G23-H23)/(Octave_1_KPIs[[#This Row],[Healthy_Min]]-Octave_1_KPIs[[#This Row],[Target_Min]]))) -> 1 | N23: Dev. Velocity & Quality | O23: Ether | P23: Is our process coherent? | Q23: "Felt Sense of Flow" | R23: ↑ | S23: 1 | T23: 4.5 | U23: N/A | V23: N/A | W23: The team's felt experience. Does the work feel like a smooth dance or a frustrating struggle? | X23: 0 | Y23: Collaborative Knowledge | Z23: Ether | AA23: Do we see our knowledge as a gift to be shared? | AB23: "Knowledge as a Commons" Mentality | AC23: ↑ | AD23: 1 | AE23: 5 | AF23: 4 | AG23: 5 | AH23: A score (1-5). The ultimate purpose behind collaborative IP. | AI23: 0 | AJ23: Embodied Innovation | AK23: Ether | AL23: Is our creation a work of art? | AM23: Beauty & Elegance of Design | AN23: ↑ | AO23: 1 | AP23: 4.8 | AQ23: N/A | AR23: N/A | AS23: A qualitative score. Does the design of our innovation (code, thesis, etc.) possess a sense of beauty and coherent elegance? | AT23: 0 | AU23: Knowledge Sharing & Influence | AV23: Ether | AW23: Is our IP becoming a standard for our field? | AX23: Influence on the Wider Discourse | AY23: ↑ | AZ23: 1 | BA23: 4 | BB23: N/A | BC23: N/A | BD23: A qualitative score. Are other thinkers, leaders, and organizations beginning to adopt our language and frameworks? | BE23: 0 | BF23: Evolution of Knowledge | BG23: Ether | BH23: Is our knowledge for the good of future generations? | BI23: Knowledge in Service of Planetary Evolution | BJ23: ↑ | BK23: 1 | BL23: 5 | BM23: N/A | BN23: N/A | BO23: The degree to which our entire R&D and IP strategy is consciously aimed at solving the deepest challenges of tomorrow. | BP23: 0 | BQ23: Knowledge as a Living Field | BR23: Ether | BS23: Is our IP a direct instrument for the planet's awakening? | BT23: Knowledge Serves Planetary Consciousness | BU23: ↑ | BV23: 1 | BW23: 5 | BX23: N/A | BY23: N/A | BZ23: The ultimate purpose. Does our knowledge act as a catalyst for a global shift in consciousness? | CA23: 0
A24: Human Capital (F3) | B24: Founder Sustainability | C24: Earth | D24: Are you rested? | E24: Average Hours of Sleep | F24: Band | G24: 8 | H24: 4 | I24: 7 | J24: 8.5 | K24: 10 | L24: The ultimate foundation of founder stability. | M24: =IF(AND(Octave_1_KPIs[[#This Row],[Value]] >= Octave_1_KPIs[[#This Row],[Healthy_Min]], Octave_1_KPIs[[#This Row],[Value]] <= Octave_1_KPIs[[#This Row],[Healthy_Max]]), 1, IF(Octave_1_KPIs[[#This Row],[Value]] < Octave_1_KPIs[[#This Row],[Healthy_Min]], MAX(0, (Octave_1_KPIs[[#This Row],[Value]] - Octave_1_KPIs[[#This Row],[Target_Min]]) / (Octave_1_KPIs[[#This Row],[Healthy_Min]] - Octave_1_KPIs[[#This Row],[Target_Min]])), MAX(0, 1 - (Octave_1_KPIs[[#This Row],[Value]] - Octave_1_KPIs[[#This Row],[Healthy_Max]]) / (Octave_1_KPIs[[#This Row],[Absolute_Max]] - Octave_1_KPIs[[#This Row],[Healthy_Max]])))) -> 1 | N24: Role Clarity & Team Stability | O24: Earth | P24: Do people know their roles? | Q24: Role Clarity Score | R24: ↑ | S24: 1 | T24: 4.5 | U24: N/A | V24: N/A | W24: A stable team is built on a foundation of clear roles and responsibilities. | X24: 0 | Y24: Team Cohesion & Psych./Safety | Z24: Earth | AA24: Is our team a safe ground for authenticity? | AB24: Psychological Safety Score | AC24: ↑ | AD24: 1 | AE24: 4.5 | AF24: N/A | AG24: N/A | AH24: A survey score (1-5). The absolute, non-negotiable bedrock of any high-performing, coherent team. | AI24: 0 | AJ24: Creative Culture | AK24: Earth | AL24: Is it safe to be a creative genius here? | AM24: Psychological Safety for "Crazy Ideas" | AN24: ↑ | AO24: 1 | AP24: 4.8 | AQ24: N/A | AR24: N/A | AS24: A survey. The bedrock of a creative culture is safety from ridicule for proposing bold, non-obvious ideas. | AT24: 0 | AU24: Cultural Storytelling | AV24: Earth | AW24: Is every team member grounded in our shared story? | AX24: Team's Ability to Articulate the "Why" | AY24: ↑ | AZ24: 0.75 | BA24: 0.95 | BB24: N/A | BC24: N/A | BD24: The % of the team that can powerfully and accurately tell the organization's origin story and purpose. | BE24: 0 | BF24: Long-Term Cultural Viability | BG24: Earth | BH24: Is our culture grounded enough to outlive its founders? | BI24: Succession Planning & Mentorship | BJ24: ↑ | BK24: 1 | BL24: 4.5 | BM24: N/A | BN24: N/A | BO24: A 1-5 score on the health of mentorship programs and the formal process for developing the next generation of leaders. | BP24: 0 | BQ24: Consciousness as Capital | BR24: Earth | BS24: Is our way of being grounded in a real, transmittable practice? | BT24: A Lineage of Mastery | BU24: ↑ | BV24: 0 | BW24: 1 | BX24: N/A | BY24: N/A | BZ24: A milestone. Has the internal culture and practice become a formal "school" or "lineage" that can train others in the art of coherence? | CA24: 0
A25: Human Capital (F3) | B25: Founder Sustainability | C25: Water | D25: Are you energized? | E25: Founder Energy Level (1-10) | F25: Band | G25: 7.5 | H25: 5 | I25: 7 | J25: 8.5 | K25: 10 | L25: The core "Plateau of Coherence" metric we have perfected. | M25: =IF(AND(Octave_1_KPIs[[#This Row],[Value]] >= Octave_1_KPIs[[#This Row],[Healthy_Min]], Octave_1_KPIs[[#This Row],[Value]] <= Octave_1_KPIs[[#This Row],[Healthy_Max]]), 1, IF(Octave_1_KPIs[[#This Row],[Value]] < Octave_1_KPIs[[#This Row],[Healthy_Min]], MAX(0, (Octave_1_KPIs[[#This Row],[Value]] - Octave_1_KPIs[[#This Row],[Target_Min]]) / (Octave_1_KPIs[[#This Row],[Healthy_Min]] - Octave_1_KPIs[[#This Row],[Target_Min]])), MAX(0, 1 - (Octave_1_KPIs[[#This Row],[Value]] - Octave_1_KPIs[[#This Row],[Healthy_Max]]) / (Octave_1_KPIs[[#This Row],[Absolute_Max]] - Octave_1_KPIs[[#This Row],[Healthy_Max]])))) -> 1 | N25: Role Clarity & Team Stability | O25: Water | P25: Is information flowing well? | Q25: Internal Comm. Efficiency | R25: ↑ | S25: 1 | T25: 4.5 | U25: N/A | V25: N/A | W25: Measures the quality of the "connective tissue" within the team. | X25: 0 | Y25: Team Cohesion & Psych./Safety | Z25: Water | AA25: Is there a strong emotional bond? | AB25: Team Cohesion / eNPS | AC25: ↑ | AD25: 0 | AE25: 70 | AF25: N/A | AG25: N/A | AH25: The classic eNPS score, measuring team morale and loyalty. | AI25: 0 | AJ25: Creative Culture | AK25: Water | AL25: Does our work environment enable deep creative flow? | AM25: "Flow State" Score | AN25: ↑ | AO25: 1 | AP25: 4.5 | AQ25: N/A | AR25: N/A | AS25: A team survey on the ability to achieve uninterrupted, deep focus. | AT25: 0 | AU25: Cultural Storytelling | AV25: Water | AW25: Do our people feel like authentic, proud ambassadors? | AX25: Employee Brand Ambassadorship | AY25: ↑ | AZ25: 0 | BA25: 70 | BB25: N/A | BC25: N/A | BD25: An "eNPS" style score. How likely are our team members to recommend our organization as a place of work and inspiration? | BE25: 0 | BF25: Long-Term Cultural Viability | BG25: Water | BH25: Is there a healthy flow of knowledge from old to new? | BI25: Inter-Generational Flow of Wisdom | BJ25: ↑ | BK25: 1 | BL25: 4.5 | BM25: N/A | BN25: N/A | BO25: How well is tacit knowledge and deep wisdom passed between senior and junior members of the team? | BP25: 0 | BQ25: Consciousness as Capital | BR25: Water | BS25: Is the emotional field of our team one of deep, resonant peace? | BT25: Collective State of Presence | BU25: ↑ | BV25: 1 | BW25: 4.8 | BX25: N/A | BY25: N/A | BZ25: A qualitative measure of the team's shared state of consciousness. Can be measured through group meditation coherence or deep intuitive sensing. | CA25: 0
A26: Human Capital (F3) | B26: Founder Sustainability | C26: Fire | D26: Are you growing? | E26: Hours Spent in Learning/Development | F26: Band | G26: 7 | H26: 0 | I26: 2 | J26: 5 | K26: 10 | L26: Measures the act of "sharpening the saw." Too little is stagnation, too much is "pro-crash-tination." | M26: =IF(AND(Octave_1_KPIs[[#This Row],[Value]] >= Octave_1_KPIs[[#This Row],[Healthy_Min]], Octave_1_KPIs[[#This Row],[Value]] <= Octave_1_KPIs[[#This Row],[Healthy_Max]]), 1, IF(Octave_1_KPIs[[#This Row],[Value]] < Octave_1_KPIs[[#This Row],[Healthy_Min]], MAX(0, (Octave_1_KPIs[[#This Row],[Value]] - Octave_1_KPIs[[#This Row],[Target_Min]]) / (Octave_1_KPIs[[#This Row],[Healthy_Min]] - Octave_1_KPIs[[#This Row],[Target_Min]])), MAX(0, 1 - (Octave_1_KPIs[[#This Row],[Value]] - Octave_1_KPIs[[#This Row],[Healthy_Max]]) / (Octave_1_KPIs[[#This Row],[Absolute_Max]] - Octave_1_KPIs[[#This Row],[Healthy_Max]])))) -> 0.6 | N26: Role Clarity & Team Stability | O26: Fire | P26: Are we retaining our talent? | Q26: Employee Retention Rate | R26: ↑ | S26: 0.7 | T26: 0.95 | U26: N/A | V26: N/A | W26: The ultimate measure of a healthy, stable culture. | X26: 0 | Y26: Team Cohesion & Psych./Safety | Z26: Fire | AA26: Do we actively and skillfully heal our dissonance/disagreements? | AB26: Conflict Resolution Time/Effectiveness | AC26: ↑ | AD26: 14d | AE26: 1d | AF26: N/A | AG26: N/A | AH26: The speed and efficiency with which interpersonal conflicts are addressed and resolved. | AI26: 0 | AJ26: Creative Culture | AK26: Fire | AL26: Do we actively make space for pure creation? | AM26: # of "Hack Days" or Creative Sprints | AN26: Band | AO26: 0 | AP26: 1 | AQ26: 2 | AR26: 4 | AS26: A healthy rhythm of dedicated, playful, creative sessions per quarter. | AT26: 0 | AU26: Cultural Storytelling | AV26: Fire | AW26: Are we actively sharing the human reality of our culture? | AX26: # of "Behind the Scenes" Cultural Stories | AY26: Band | AZ26: 0 | BA26: 2 | BB26: 5 | BC26: 10 | BD26: A sustainable rhythm of authentic, internal storytelling made public per month. | BE26: 0 | BF26: Long-Term Cultural Viability | BG26: Fire | BH26: Are we actively forging the leaders of tomorrow? | BI26: Leadership Development Programs | BJ26: Band | BK26: 0 | BL26: 1 | BM26: 2 | BN26: 3 | BO26: A sustainable rhythm of formal programs designed to cultivate the next wave of coherent leadership. | BP26: 0 | BQ26: Consciousness as Capital | BR26: Fire | BS26: Does the very presence of our team create a healing ripple in the world? | BT26: Team as a Source of Global Awakening | BU26: ↑ | BV26: 1 | BW26: 4.5 | BX26: N/A | BY26: N/A | BZ26: The degree to which team members, in all their interactions, act as ambassadors of coherence and inspiration to the wider world. | CA26: 0
